Workbook
Name _GoBack: Orden!$A$2

Sheet Equipos
B1: Torneo Fútbol 7 San José
B2: Equipos | D2: Tablas
B3: Los Amigos | D3: Tablas
B4: La Nueva Era | D4: Jugadores
B5: La Amistad | D5: Resultados
B6: Konami | D6: Fixture
B7: Villanueva
B8: Ron Star
B9: Amenadim
B10: Hojas Anchas
B11: Valentín FC
B12: Boca Juniors
B13: Deportivo Fénix
B14: Rayos FC
B15: La Unión FC
B16: Los Aliados
B17: Atalanta
B18: CD El Corozo

Sheet Fixture
A1: Volver
A2: Fecha 1 | B2: 1 | C2: 45676 | D2: Atalanta | E2: Vs | F2: La Amistad
B3: 2 | C3: 45676 | D3: Rayos FC | E3: Vs | F3: Ron Star
B4: 3 | C4: 45676 | D4: Deportivo Fénix | E4: Vs | F4: Amenadim
B5: 4 | C5: 45676 | D5: La Nueva Era | E5: Vs | F5: Los Amigos
B6: 5 | C6: 45676 | D6: Boca Juniors | E6: Vs | F6: Hojas Anchas
B7: 6 | C7: 45676 | D7: La Unión FC | E7: Vs | F7: Villanueva
B8: 7 | C8: 45809 | D8: Valentín FC | E8: Vs | F8: Los Aliados
B9: 8 | C9: 45809 | D9: CD El Corozo | E9: Vs | F9: Konami
A10: Fecha 2 | B10: 9 | C10: 45683 | D10: Atalanta | E10: Vs | F10: Konami
B11: 10 | C11: 45683 | D11: Valentín FC | E11: Vs | F11: La Nueva Era
B12: 11 | C12: 45683 | D12: Deportivo Fénix | E12: Vs | F12: Hojas Anchas
B13: 12 | C13: 45683 | D13: Rayos FC | E13: Vs | F13: Amenadim
B14: 13 | C14: 45683 | D14: La Unión FC | E14: Vs | F14: Ron Star
B15: 14 | C15: 45683 | D15: La Amistad | E15: Vs | F15: Los Amigos
B16: 15 | C16: 45683 | D16: Boca Juniors | E16: Vs | F16: Los Aliados
B17: 16 | C17: 45704 | D17: CD El Corozo | E17: Vs | F17: Villanueva
A18: Fecha 3 | B18: 17 | C18: 45690 | D18: La Unión FC | E18: Vs | F18: La Amistad
B19: 18 | C19: 45690 | D19: Los Aliados | E19: Vs | F19: Amenadim
B20: 19 | C20: 45690 | D20: Valentín FC | E20: Vs | F20: Hojas Anchas
B21: 20 | C21: 45690 | D21: Boca Juniors | E21: Vs | F21: Ron Star
B22: 21 | C22: 45690 | D22: Atalanta | E22: Vs | F22: Los Amigos
B23: 22 | C23: 45690 | D23: Rayos FC | E23: Vs | F23: Konami
B24: 23 | C24: 45690 | D24: Deportivo Fénix | E24: Vs | F24: Villanueva
B25: 24 | C25: 45774 | D25: CD El Corozo | E25: Vs | F25: La Nueva Era
A26: Fecha 4 | B26: 25 | C26: 45697 | D26: Konami | E26: Vs | F26: La Nueva Era
B27: 26 | C27: 45697 | D27: Valentín FC | E27: Vs | F27: La Amistad
B28: 27 | C28: 45697 | D28: CD El Corozo | E28: Vs | F28: Amenadim
B29: 28 | C29: 45697 | D29: Rayos FC | E29: Vs | F29: Los Aliados
B30: 29 | C30: 45697 | D30: Villanueva | E30: Vs | F30: Los Amigos
B31: 30 | C31: 45697 | D31: Deportivo Fénix | E31: Vs | F31: Boca Juniors
B32: 31 | C32: 45697 | D32: La Unión FC | E32: Vs | F32: Hojas Anchas
B33: 32 | C33: 45697 | D33: Atalanta | E33: Vs | F33: Ron Star
A34: Fecha 5 | B34: 33 | C34: 45704 | D34: La Unión FC | E34: Vs | F34: Los Aliados
B35: 34 | C35: 45704 | D35: Villanueva | E35: Vs | F35: La Nueva Era
B36: 35 | C36: 45704 | D36: Ron Star | E36: Vs | F36: Los Amigos
B37: 36 | C37: 45704 | D37: CD El Corozo | E37: Vs | F37: Hojas Anchas
B38: 37 | C38: 45704 | D38: Atalanta | E38: Vs | F38: Amenadim
B39: 38 | C39: 45704 | D39: Valentín FC | E39: Vs | F39: Deportivo Fénix
B40: 39 | C40: 45704 | D40: Konami | E40: Vs | F40: La Amistad
...

Sheet Tablas
A1: Clasificación | L1: Tabla de Goleadores | R1: Amonestados | W1: Doble Amonestación | AB1: Expulsiones
A2: Pos. | B2: Equipo | C2: G | D2: E | E2: P | F2: JL | G2: GF:GC | H2: Pts. | I2: DG | J2: PJ | L2: Pos | N2: Jugador | O2: Equipo | P2: Goles | R2: Ord. | S2: Jugador | T2: Equipo | U2: Cant. | W2: Ord. | X2: Jugador | Y2: Equipo | Z2: Cant. | AB2: Ord. | AC2: Jugador | AD2: Equipo | AE2: Cant.
A3: 1° | B3: =Resultados!AC3 -> La Unión FC | C3: =Resultados!AE3 -> 16 | D3: =Resultados!AF3 -> 4 | E3: =Resultados!AG3 -> 2 | F3: =Resultados!AK3 -> 205 | G3: =CONCATENATE(Resultados!AH3,":",Resultados!AI3) -> 118:57 | H3: =Resultados!AL3 -> 52 | I3: =Resultados!AJ3 -> 61 | J3: =Resultados!AD3 -> 22 | L3: 1° | N3: =Orden!F2 -> Alexander Salgado | O3: =Orden!G2 -> La Unión FC | P3: =Orden!H2 -> 49 | R3: 1° | S3: =Orden!K2 -> Carlos Andrés Berrio | T3: =Orden!L2 -> Valentín FC | U3: =Orden!M2 -> 9 | W3: 1° | X3: =Orden!P2 | Y3: =Orden!Q2 | Z3: =Orden!R2 | AB3: 1° | AC3: =Orden!U2 | AD3: =Orden!V2 | AE3: =Orden!W2
A4: 2° | B4: =Resultados!AC4 -> Ron Star | C4: =Resultados!AE4 -> 16 | D4: =Resultados!AF4 -> 3 | E4: =Resultados!AG4 -> 5 | F4: =Resultados!AK4 -> 90 | G4: =CONCATENATE(Resultados!AH4,":",Resultados!AI4) -> 101:53 | H4: =Resultados!AL4 -> 51 | I4: =Resultados!AJ4 -> 48 | J4: =Resultados!AD4 -> 24 | L4: 2° | N4: =Orden!F3 -> Eliecer Serpa | O4: =Orden!G3 -> Ron Star | P4: =Orden!H3 -> 41 | R4: 2° | S4: =Orden!K3 -> Julián Esteban Gil | T4: =Orden!L3 -> Hojas Anchas | U4: =Orden!M3 -> 7 | W4: 2° | X4: =Orden!P3 | Y4: =Orden!Q3 | Z4: =Orden!R3 | AB4: 2° | AC4: =Orden!U3 | AD4: =Orden!V3 | AE4: =Orden!W3
A5: 3° | B5: =Resultados!AC5 -> La Amistad | C5: =Resultados!AE5 -> 16 | D5: =Resultados!AF5 -> 2 | E5: =Resultados!AG5 -> 3 | F5: =Resultados!AK5 -> 120 | G5: =CONCATENATE(Resultados!AH5,":",Resultados!AI5) -> 100:43 | H5: =Resultados!AL5 -> 50 | I5: =Resultados!AJ5 -> 57 | J5: =Resultados!AD5 -> 21 | L5: 3° | N5: =Orden!F4 -> Hernán Sánchez | O5: =Orden!G4 -> Los Amigos | P5: =Orden!H4 -> 30 | R5: 3° | S5: =Orden!K4 -> Argemiro Medina | T5: =Orden!L4 -> Ron Star | U5: =Orden!M4 -> 5 | W5: 3° | X5: =Orden!P4 | Y5: =Orden!Q4 | Z5: =Orden!R4 | AB5: 3° | AC5: =Orden!U4 | AD5: =Orden!V4 | AE5: =Orden!W4
A6: 4° | B6: =Resultados!AC6 -> Los Amigos | C6: =Resultados!AE6 -> 15 | D6: =Resultados!AF6 -> 5 | E6: =Resultados!AG6 -> 4 | F6: =Resultados!AK6 -> 135 | G6: =CONCATENATE(Resultados!AH6,":",Resultados!AI6) -> 105:60 | H6: =Resultados!AL6 -> 50 | I6: =Resultados!AJ6 -> 45 | J6: =Resultados!AD6 -> 24 | L6: 4° | N6: =Orden!F5 -> Jaider Carvajal Ríos | O6: =Orden!G5 -> Valentín FC | P6: =Orden!H5 -> 27 | R6: 4° | S6: =Orden!K5 -> Jaider Carvajal Ríos | T6: =Orden!L5 -> Valentín FC | U6: =Orden!M5 -> 5 | W6: 4° | X6: =Orden!P5 | Y6: =Orden!Q5 | Z6: =Orden!R5 | AB6: 4° | AC6: =Orden!U5 | AD6: =Orden!V5 | AE6: =Orden!W5
A7: 5° | B7: =Resultados!AC7 -> Konami | C7: =Resultados!AE7 -> 15 | D7: =Resultados!AF7 -> 1 | E7: =Resultados!AG7 -> 7 | F7: =Resultados!AK7 -> 45 | G7: =CONCATENATE(Resultados!AH7,":",Resultados!AI7) -> 75:41 | H7: =Resultados!AL7 -> 46 | I7: =Resultados!AJ7 -> 34 | J7: =Resultados!AD7 -> 23 | L7: 5° | N7: =Orden!F6 -> Santiago Lopera | O7: =Orden!G6 -> Konami | P7: =Orden!H6 -> 25 | R7: 5° | S7: =Orden!K6 -> Luis Fernando Madera | T7: =Orden!L6 -> La Unión FC | U7: =Orden!M6 -> 5 | W7: 5° | X7: =Orden!P6 | Y7: =Orden!Q6 | Z7: =Orden!R6 | AB7: 5° | AC7: =Orden!U6 | AD7: =Orden!V6 | AE7: =Orden!W6
A8: 6° | B8: =Resultados!AC8 -> Valentín FC | C8: =Resultados!AE8 -> 13 | D8: =Resultados!AF8 -> 5 | E8: =Resultados!AG8 -> 6 | F8: =Resultados!AK8 -> 230 | G8: =CONCATENATE(Resultados!AH8,":",Resultados!AI8) -> 88:46 | H8: =Resultados!AL8 -> 44 | I8: =Resultados!AJ8 -> 42 | J8: =Resultados!AD8 -> 24 | L8: 6° | N8: =Orden!F7 -> Alexander Silva | O8: =Orden!G7 -> Villanueva | P8: =Orden!H7 -> 24 | R8: 6° | S8: =Orden!K7 -> Daniel Ossa | T8: =Orden!L7 -> Los Amigos | U8: =Orden!M7 -> 4 | W8: 6° | X8: =Orden!P7 | Y8: =Orden!Q7 | Z8: =Orden!R7 | AB8: 6° | AC8: =Orden!U7 | AD8: =Orden!V7 | AE8: =Orden!W7
A9: 7° | B9: =Resultados!AC9 -> Villanueva | C9: =Resultados!AE9 -> 13 | D9: =Resultados!AF9 -> 1 | E9: =Resultados!AG9 -> 7 | F9: =Resultados!AK9 -> 170 | G9: =CONCATENATE(Resultados!AH9,":",Resultados!AI9) -> 71:43 | H9: =Resultados!AL9 -> 40 | I9: =Resultados!AJ9 -> 28 | J9: =Resultados!AD9 -> 21 | L9: 7° | N9: =Orden!F8 -> Brayan Salazar Gómez | O9: =Orden!G8 -> La Amistad | P9: =Orden!H8 -> 23 | R9: 7° | S9: =Orden!K8 -> Ángel Mora | T9: =Orden!L8 -> Villanueva | U9: =Orden!M8 -> 4 | W9: 7° | X9: =Orden!P8 | Y9: =Orden!Q8 | Z9: =Orden!R8 | AB9: 7° | AC9: =Orden!U8 | AD9: =Orden!V8 | AE9: =Orden!W8
A10: 8° | B10: =Resultados!AC10 -> Amenadim | C10: =Resultados!AE10 -> 10 | D10: =Resultados!AF10 -> 1 | E10: =Resultados!AG10 -> 10 | F10: =Resultados!AK10 -> 95 | G10: =CONCATENATE(Resultados!AH10,":",Resultados!AI10) -> 70:59 | H10: =Resultados!AL10 -> 31 | I10: =Resultados!AJ10 -> 11 | J10: =Resultados!AD10 -> 21 | L10: 8° | N10: =Orden!F9 -> Yehis Pacheco | O10: =Orden!G9 -> Boca Juniors | P10: =Orden!H9 -> 20 | R10: 8° | S10: =Orden!K9 -> Julián Hincapie | T10: =Orden!L9 -> Ron Star | U10: =Orden!M9 -> 4 | W10: 8° | X10: =Orden!P9 | Y10: =Orden!Q9 | Z10: =Orden!R9 | AB10: 8° | AC10: =Orden!U9 | AD10: =Orden!V9 | AE10: =Orden!W9
A11: 9° | B11: =Resultados!AC11 -> Boca Juniors | C11: =Resultados!AE11 -> 9 | D11: =Resultados!AF11 -> 1 | E11: =Resultados!AG11 -> 12 | F11: =Resultados!AK11 -> 185 | G11: =CONCATENATE(Resultados!AH11,":",Resultados!AI11) -> 59:65 | H11: =Resultados!AL11 -> 28 | I11: =Resultados!AJ11 -> -6 | J11: =Resultados!AD11 -> 22 | L11: 9° | N11: =Orden!F10 -> Juan Manuel Marulanda | O11: =Orden!G10 -> La Amistad | P11: =Orden!H10 -> 19 | R11: 9° | S11: =Orden!K10 -> Martín Angulo | T11: =Orden!L10 -> Amenadim | U11: =Orden!M10 -> 4 | W11: 9° | X11: =Orden!P10 | Y11: =Orden!Q10 | Z11: =Orden!R10 | AB11: 9° | AC11: =Orden!U10 | AD11: =Orden!V10 | AE11: =Orden!W10
A12: 10° | B12: =Resultados!AC12 -> CD El Corozo | C12: =Resultados!AE12 -> 8 | D12: =Resultados!AF12 -> 3 | E12: =Resultados!AG12 -> 10 | F12: =Resultados!AK12 -> 240 | G12: =CONCATENATE(Resultados!AH12,":",Resultados!AI12) -> 67:54 | H12: =Resultados!AL12 -> 27 | I12: =Resultados!AJ12 -> 13 | J12: =Resultados!AD12 -> 21 | L12: 10° | N12: =Orden!F11 -> Denilson Cadena | O12: =Orden!G11 -> Villanueva | P12: =Orden!H11 -> 19 | R12: 10° | S12: =Orden!K11 -> Matias Montoya | T12: =Orden!L11 -> Valentín FC | U12: =Orden!M11 -> 4 | W12: 10° | X12: =Orden!P11 | Y12: =Orden!Q11 | Z12: =Orden!R11 | AB12: 10° | AC12: =Orden!U11 | AD12: =Orden!V11 | AE12: =Orden!W11
A13: 11° | B13: =Resultados!AC13 -> Hojas Anchas | C13: =Resultados!AE13 -> 6 | D13: =Resultados!AF13 -> 5 | E13: =Resultados!AG13 -> 11 | F13: =Resultados!AK13 -> 225 | G13: =CONCATENATE(Resultados!AH13,":",Resultados!AI13) -> 66:85 | H13: =Resultados!AL13 -> 23 | I13: =Resultados!AJ13 -> -19 | J13: =Resultados!AD13 -> 22 | R13: 11° | S13: =Orden!K12 -> Cristián Duque | T13: =Orden!L12 -> Valentín FC | U13: =Orden!M12 -> 4 | W13: 11° | X13: =Orden!P12 | Y13: =Orden!Q12 | Z13: =Orden!R12 | AB13: 11° | AC13: =Orden!U12 | AD13: =Orden!V12 | AE13: =Orden!W12
A14: 12° | B14: =Resultados!AC14 -> Deportivo Fénix | C14: =Resultados!AE14 -> 7 | D14: =Resultados!AF14 -> 1 | E14: =Resultados!AG14 -> 13 | F14: =Resultados!AK14 -> 90 | G14: =CONCATENATE(Resultados!AH14,":",Resultados!AI14) -> 54:103 | H14: =Resultados!AL14 -> 22 | I14: =Resultados!AJ14 -> -49 | J14: =Resultados!AD14 -> 21 | R14: 12° | S14: =Orden!K13 -> Daniel Garcia | T14: =Orden!L13 -> Boca Juniors | U14: =Orden!M13 -> 4 | W14: 12° | X14: =Orden!P13 | Y14: =Orden!Q13 | Z14: =Orden!R13 | AB14: 12° | AC14: =Orden!U13 | AD14: =Orden!V13 | AE14: =Orden!W13
A15: 13° | B15: =Resultados!AC15 -> Los Aliados | C15: =Resultados!AE15 -> 4 | D15: =Resultados!AF15 -> 2 | E15: =Resultados!AG15 -> 16 | F15: =Resultados!AK15 -> 195 | G15: =CONCATENATE(Resultados!AH15,":",Resultados!AI15) -> 39:111 | H15: =Resultados!AL15 -> 14 | I15: =Resultados!AJ15 -> -72 | J15: =Resultados!AD15 -> 22 | R15: 13° | S15: =Orden!K14 -> Arbenis Montoya | T15: =Orden!L14 -> Boca Juniors | U15: =Orden!M14 -> 4 | W15: 13° | X15: =Orden!P14 | Y15: =Orden!Q14 | Z15: =Orden!R14 | AB15: 13° | AC15: =Orden!U14 | AD15: =Orden!V14 | AE15: =Orden!W14
A16: 14° | B16: =Resultados!AC16 -> Atalanta | C16: =Resultados!AE16 -> 3 | D16: =Resultados!AF16 -> 4 | E16: =Resultados!AG16 -> 15 | F16: =Resultados!AK16 -> 210 | G16: =CONCATENATE(Resultados!AH16,":",Resultados!AI16) -> 50:94 | H16: =Resultados!AL16 -> 13 | I16: =Resultados!AJ16 -> -44 | J16: =Resultados!AD16 -> 22 | R16: 14° | S16: =Orden!K15 -> Oscar Torín | T16: =Orden!L15 -> Boca Juniors | U16: =Orden!M15 -> 4 | W16: 14° | X16: =Orden!P15 | Y16: =Orden!Q15 | Z16: =Orden!R15 | AB16: 14° | AC16: =Orden!U15 | AD16: =Orden!V15 | AE16: =Orden!W15
A17: 15° | B17: =Resultados!AC17 -> La Nueva Era | C17: =Resultados!AE17 -> 4 | D17: =Resultados!AF17 -> 0 | E17: =Resultados!AG17 -> 17 | F17: =Resultados!AK17 -> 50 | G17: =CONCATENATE(Resultados!AH17,":",Resultados!AI17) -> 38:133 | H17: =Resultados!AL17 -> 12 | I17: =Resultados!AJ17 -> -95 | J17: =Resultados!AD17 -> 21 | R17: 15° | S17: =Orden!K17 -> Alexander Salgado | T17: =Orden!L17 -> La Unión FC | U17: =Orden!M17 -> 4 | W17: 15° | X17: =Orden!P17 | Y17: =Orden!Q17 | Z17: =Orden!R17 | AB17: 15° | AC17: =Orden!U17 | AD17: =Orden!V17 | AE17: =Orden!W17
A18: 16° | B18: =Resultados!AC18 -> Rayos FC | C18: =Resultados!AE18 -> 1 | D18: =Resultados!AF18 -> 0 | E18: =Resultados!AG18 -> 14 | F18: =Resultados!AK18 -> 370 | G18: =CONCATENATE(Resultados!AH18,":",Resultados!AI18) -> 6:50 | H18: =Resultados!AL18 -> 3 | I18: =Resultados!AJ18 -> -44 | J18: =Resultados!AD18 -> 15 | R18: 16° | S18: =Orden!K18 -> Deiner Santana | T18: =Orden!L18 -> La Unión FC | U18: =Orden!M18 -> 4 | W18: 16° | X18: =Orden!P18 | Y18: =Orden!Q18 | Z18: =Orden!R18 | AB18: 16° | AC18: =Orden!U18 | AD18: =Orden!V18 | AE18: =Orden!W18
R19: 17° | S19: =Orden!K19 -> Jhon Restrepo | T19: =Orden!L19 -> Los Amigos | U19: =Orden!M19 -> 3 | W19: 17° | X19: =Orden!P19 | Y19: =Orden!Q19 | Z19: =Orden!R19 | AB19: 17° | AC19: =Orden!U19 | AD19: =Orden!V19 | AE19: =Orden!W19
R20: 18° | S20: =Orden!K20 -> Julián Botero Carvajal | T20: =Orden!L20 -> La Nueva Era | U20: =Orden!M20 -> 3 | W20: 18° | X20: =Orden!P20 | Y20: =Orden!Q20 | Z20: =Orden!R20 | AB20: 18° | AC20: =Orden!U20 | AD20: =Orden!V20 | AE20: =Orden!W20
A21: Grupo A | R21: 19° | S21: =Orden!K21 -> Deivid Jaramillo | T21: =Orden!L21 -> La Amistad | U21: =Orden!M21 -> 3 | W21: 19° | X21: =Orden!P21 | Y21: =Orden!Q21 | Z21: =Orden!R21 | AB21: 19° | AC21: =Orden!U21 | AD21: =Orden!V21 | AE21: =Orden!W21
A22: Pos. | B22: Equipo | C22: G | D22: E | E22: P | F22: JL | G22: GF | H22: Pts. | I22: DG | J22: PJ | R22: 20° | S22: =Orden!K22 -> Humberto Ochoa | T22: =Orden!L22 -> Amenadim | U22: =Orden!M22 -> 3 | W22: 20° | X22: =Orden!P22 | Y22: =Orden!Q22 | Z22: =Orden!R22 | AB22: 20° | AC22: =Orden!U22 | AD22: =Orden!V22 | AE22: =Orden!W22
A23: 1° | B23: =Resultados!AC56 -> Valentín FC | C23: =Resultados!AD56 -> 6 | D23: =Resultados!AE56 -> 0 | E23: =Resultados!AF56 -> 1 | F23: =VLOOKUP($B23,$B$3:$J$18,5,FALSE) -> 230 | G23: =CONCATENATE(Resultados!AG56,":",Resultados!AH56) -> 29:7 | H23: =Resultados!AJ56 -> 18 | I23: =Resultados!AI56 -> 22 | J23: =Resultados!AK56 -> 7 | R23: 21° | S23: =Orden!K23 -> Edwar Jaramillo | T23: =Orden!L23 -> Hojas Anchas | U23: =Orden!M23 -> 3 | W23: 21° | X23: =Orden!P23 | Y23: =Orden!Q23 | Z23: =Orden!R23 | AB23: 21° | AC23: =Orden!U23 | AD23: =Orden!V23 | AE23: =Orden!W23
A24: 2° | B24: =Resultados!AC57 -> La Unión FC | C24: =Resultados!AD57 -> 5 | D24: =Resultados!AE57 -> 1 | E24: =Resultados!AF57 -> 1 | F24: =VLOOKUP($B24,$B$3:$J$18,5,FALSE) -> 205 | G24: =CONCATENATE(Resultados!AG57,":",Resultados!AH57) -> 35:11 | H24: =Resultados!AJ57 -> 16 | I24: =Resultados!AI57 -> 24 | J24: =Resultados!AK57 -> 7 | R24: 22° | S24: =Orden!K24 -> Jaider Londoño | T24: =Orden!L24 -> Hojas Anchas | U24: =Orden!M24 -> 3 | W24: 22° | X24: =Orden!P24 | Y24: =Orden!Q24 | Z24: =Orden!R24 | AB24: 22° | AC24: =Orden!U24 | AD24: =Orden!V24 | AE24: =Orden!W24
A25: 3° | B25: =Resultados!AC58 -> Los Amigos | C25: =Resultados!AD58 -> 5 | D25: =Resultados!AE58 -> 1 | E25: =Resultados!AF58 -> 1 | F25: =VLOOKUP($B25,$B$3:$J$18,5,FALSE) -> 135 | G25: =CONCATENATE(Resultados!AG58,":",Resultados!AH58) -> 32:17 | H25: =Resultados!AJ58 -> 16 | I25: =Resultados!AI58 -> 15 | J25: =Resultados!AK58 -> 7 | R25: 23° | S25: =Orden!K25 -> José Ángel Londoño | T25: =Orden!L25 -> Hojas Anchas | U25: =Orden!M25 -> 3 | W25: 23° | X25: =Orden!P25 | Y25: =Orden!Q25 | Z25: =Orden!R25 | AB25: 23° | AC25: =Orden!U25 | AD25: =Orden!V25 | AE25: =Orden!W25
A26: 4° | B26: =Resultados!AC59 -> Ron Star | C26: =Resultados!AD59 -> 4 | D26: =Resultados!AE59 -> 2 | E26: =Resultados!AF59 -> 1 | F26: =VLOOKUP($B26,$B$3:$J$18,5,FALSE) -> 90 | G26: =CONCATENATE(Resultados!AG59,":",Resultados!AH59) -> 25:16 | H26: =Resultados!AJ59 -> 14 | I26: =Resultados!AI59 -> 9 | J26: =Resultados!AK59 -> 7 | R26: 24° | S26: =Orden!K26 -> Jeferson Álvarez | T26: =Orden!L26 -> Hojas Anchas | U26: =Orden!M26 -> 3 | W26: 24° | X26: =Orden!P26 | Y26: =Orden!Q26 | Z26: =Orden!R26 | AB26: 24° | AC26: =Orden!U26 | AD26: =Orden!V26 | AE26: =Orden!W26
A27: 5° | B27: =Resultados!AC60 -> Atalanta | C27: =Resultados!AD60 -> 2 | D27: =Resultados!AE60 -> 1 | E27: =Resultados!AF60 -> 4 | F27: =VLOOKUP($B27,$B$3:$J$18,5,FALSE) -> 210 | G27: =CONCATENATE(Resultados!AG60,":",Resultados!AH60) -> 26:37 | H27: =Resultados!AJ60 -> 7 | I27: =Resultados!AI60 -> -11 | J27: =Resultados!AK60 -> 7 | R27: 25° | S27: =Orden!K27 -> Alejandro Acevedo | T27: =Orden!L27 -> Valentín FC | U27: =Orden!M27 -> 3 | W27: 25° | X27: =Orden!P27 | Y27: =Orden!Q27 | Z27: =Orden!R27 | AB27: 25° | AC27: =Orden!U27 | AD27: =Orden!V27 | AE27: =Orden!W27
A28: 6° | B28: =Resultados!AC61 -> Hojas Anchas | C28: =Resultados!AD61 -> 2 | D28: =Resultados!AE61 -> 0 | E28: =Resultados!AF61 -> 5 | F28: =VLOOKUP($B28,$B$3:$J$18,5,FALSE) -> 225 | G28: =CONCATENATE(Resultados!AG61,":",Resultados!AH61) -> 25:33 | H28: =Resultados!AJ61 -> 6 | I28: =Resultados!AI61 -> -8 | J28: =Resultados!AK61 -> 7 | R28: 26° | S28: =Orden!K28 -> Victor Sierra | T28: =Orden!L28 -> Valentín FC | U28: =Orden!M28 -> 3 | W28: 26° | X28: =Orden!P28 | Y28: =Orden!Q28 | Z28: =Orden!R28 | AB28: 26° | AC28: =Orden!U28 | AD28: =Orden!V28 | AE28: =Orden!W28
A29: 7° | B29: =Resultados!AC62 -> Los Aliados | C29: =Resultados!AD62 -> 1 | D29: =Resultados!AE62 -> 0 | E29: =Resultados!AF62 -> 6 | F29: =VLOOKUP($B29,$B$3:$J$18,5,FALSE) -> 195 | G29: =CONCATENATE(Resultados!AG62,":",Resultados!AH62) -> 10:43 | H29: =Resultados!AJ62 -> 3 | I29: =Resultados!AI62 -> -33 | J29: =Resultados!AK62 -> 7 | R29: 27° | S29: =Orden!K29 -> Orlando Montiel | T29: =Orden!L29 -> Boca Juniors | U29: =Orden!M29 -> 3 | W29: 27° | X29: =Orden!P29 | Y29: =Orden!Q29 | Z29: =Orden!R29 | AB29: 27° | AC29: =Orden!U29 | AD29: =Orden!V29 | AE29: =Orden!W29
A30: 8° | B30: =Resultados!AC63 -> Boca Juniors | C30: =Resultados!AD63 -> 0 | D30: =Resultados!AE63 -> 1 | E30: =Resultados!AF63 -> 6 | F30: =VLOOKUP($B30,$B$3:$J$18,5,FALSE) -> 185 | G30: =CONCATENATE(Resultados!AG63,":",Resultados!AH63) -> 11:29 | H30: =Resultados!AJ63 -> 1 | I30: =Resultados!AI63 -> -18 | J30: =Resultados!AK63 -> 7 | R30: 28° | S30: =Orden!K30 -> Andry Jhoan Rivera | T30: =Orden!L30 -> Boca Juniors | U30: =Orden!M30 -> 3 | W30: 28° | X30: =Orden!P30 | Y30: =Orden!Q30 | Z30: =Orden!R30 | AB30: 28° | AC30: =Orden!U30 | AD30: =Orden!V30 | AE30: =Orden!W30
R31: 29° | S31: =Orden!K32 -> Jhoan Sebastián Ossa | T31: =Orden!L32 -> Los Aliados | U31: =Orden!M32 -> 3 | W31: 29° | X31: =Orden!P32 | Y31: =Orden!Q32 | Z31: =Orden!R32 | AB31: 29° | AC31: =Orden!U32 | AD31: =Orden!V32 | AE31: =Orden!W32
A32: Grupo B | R32: 30° | S32: =Orden!K33 -> Manuel Carrascal Espitía | T32: =Orden!L33 -> CD El Corozo | U32: =Orden!M33 -> 3 | W32: 30° | X32: =Orden!P33 | Y32: =Orden!Q33 | Z32: =Orden!R33 | AB32: 30° | AC32: =Orden!U33 | AD32: =Orden!V33 | AE32: =Orden!W33
A33: Pos. | B33: Equipo | C33: G | D33: E | E33: P | F33: JL | G33: GF | H33: Pts. | I33: DG | J33: PJ | R33: 31° | S33: =Orden!K34 -> Cristián Álzate | T33: =Orden!L34 -> Los Amigos | U33: =Orden!M34 -> 2 | W33: 31° | X33: =Orden!P34 | Y33: =Orden!Q34 | Z33: =Orden!R34 | AB33: 31° | AC33: =Orden!U34 | AD33: =Orden!V34 | AE33: =Orden!W34
A34: 1° | B34: =Resultados!AC67 -> La Amistad | C34: =Resultados!AD67 -> 6 | D34: =Resultados!AE67 -> 0 | E34: =Resultados!AF67 -> 0 | F34: =VLOOKUP($B34,$B$3:$J$18,5,FALSE) -> 120 | G34: =CONCATENATE(Resultados!AG67,":",Resultados!AH67) -> 35:9 | H34: =Resultados!AJ67 -> 18 | I34: =Resultados!AI67 -> 26 | J34: =Resultados!AK67 -> 6 | R34: 32° | S34: =Orden!K35 -> Santiago Cardona | T34: =Orden!L35 -> Los Amigos | U34: =Orden!M35 -> 2 | W34: 32° | X34: =Orden!P35 | Y34: =Orden!Q35 | Z34: =Orden!R35 | AB34: 32° | AC34: =Orden!U35 | AD34: =Orden!V35 | AE34: =Orden!W35
A35: 2° | B35: =Resultados!AC68 -> Villanueva | C35: =Resultados!AD68 -> 5 | D35: =Resultados!AE68 -> 0 | E35: =Resultados!AF68 -> 1 | F35: =VLOOKUP($B35,$B$3:$J$18,5,FALSE) -> 170 | G35: =CONCATENATE(Resultados!AG68,":",Resultados!AH68) -> 22:8 | H35: =Resultados!AJ68 -> 15 | I35: =Resultados!AI68 -> 14 | J35: =Resultados!AK68 -> 6 | R35: 33° | S35: =Orden!K36 -> Diego Castrillón | T35: =Orden!L36 -> Los Amigos | U35: =Orden!M36 -> 2 | W35: 33° | X35: =Orden!P36 | Y35: =Orden!Q36 | Z35: =Orden!R36 | AB35: 33° | AC35: =Orden!U36 | AD35: =Orden!V36 | AE35: =Orden!W36
A36: 3° | B36: =Resultados!AC69 -> Konami | C36: =Resultados!AD69 -> 4 | D36: =Resultados!AE69 -> 0 | E36: =Resultados!AF69 -> 2 | F36: =VLOOKUP($B36,$B$3:$J$18,5,FALSE) -> 45 | G36: =CONCATENATE(Resultados!AG69,":",Resultados!AH69) -> 12:9 | H36: =Resultados!AJ69 -> 12 | I36: =Resultados!AI69 -> 3 | J36: =Resultados!AK69 -> 6 | R36: 34° | S36: =Orden!K37 -> Hernán Sánchez | T36: =Orden!L37 -> Los Amigos | U36: =Orden!M37 -> 2 | W36: 34° | X36: =Orden!P37 | Y36: =Orden!Q37 | Z36: =Orden!R37 | AB36: 34° | AC36: =Orden!U37 | AD36: =Orden!V37 | AE36: =Orden!W37
A37: 4° | B37: =Resultados!AC70 -> Amenadim | C37: =Resultados!AD70 -> 3 | D37: =Resultados!AE70 -> 0 | E37: =Resultados!AF70 -> 3 | F37: =VLOOKUP($B37,$B$3:$J$18,5,FALSE) -> 95 | G37: =CONCATENATE(Resultados!AG70,":",Resultados!AH70) -> 19:16 | H37: =Resultados!AJ70 -> 9 | I37: =Resultados!AI70 -> 3 | J37: =Resultados!AK70 -> 6 | R37: 35° | S37: =Orden!K38 -> Gonzalo Carvajal | T37: =Orden!L38 -> La Nueva Era | U37: =Orden!M38 -> 2 | W37: 35° | X37: =Orden!P38 | Y37: =Orden!Q38 | Z37: =Orden!R38 | AB37: 35° | AC37: =Orden!U38 | AD37: =Orden!V38 | AE37: =Orden!W38
A38: 5° | B38: =Resultados!AC71 -> Deportivo Fénix | C38: =Resultados!AD71 -> 2 | D38: =Resultados!AE71 -> 0 | E38: =Resultados!AF71 -> 4 | F38: =VLOOKUP($B38,$B$3:$J$18,5,FALSE) -> 90 | G38: =CONCATENATE(Resultados!AG71,":",Resultados!AH71) -> 15:22 | H38: =Resultados!AJ71 -> 6 | I38: =Resultados!AI71 -> -7 | J38: =Resultados!AK71 -> 6 | R38: 36° | S38: =Orden!K39 -> Antony Pérez Osorio | T38: =Orden!L39 -> La Amistad | U38: =Orden!M39 -> 2 | W38: 36° | X38: =Orden!P39 | Y38: =Orden!Q39 | Z38: =Orden!R39 | AB38: 36° | AC38: =Orden!U39 | AD38: =Orden!V39 | AE38: =Orden!W39
A39: 6° | B39: =Resultados!AC72 -> La Nueva Era | C39: =Resultados!AD72 -> 1 | D39: =Resultados!AE72 -> 0 | E39: =Resultados!AF72 -> 5 | F39: =VLOOKUP($B39,$B$3:$J$18,5,FALSE) -> 50 | G39: =CONCATENATE(Resultados!AG72,":",Resultados!AH72) -> 5:28 | H39: =Resultados!AJ72 -> 3 | I39: =Resultados!AI72 -> -23 | J39: =Resultados!AK72 -> 6 | R39: 37° | S39: =Orden!K40 -> Juan David García | T39: =Orden!L40 -> La Amistad | U39: =Orden!M40 -> 2 | W39: 37° | X39: =Orden!P40 | Y39: =Orden!Q40 | Z39: =Orden!R40 | AB39: 37° | AC39: =Orden!U40 | AD39: =Orden!V40 | AE39: =Orden!W40
A40: 7° | B40: =Resultados!AC73 -> CD El Corozo | C40: =Resultados!AD73 -> 0 | D40: =Resultados!AE73 -> 0 | E40: =Resultados!AF73 -> 6 | F40: =VLOOKUP($B40,$B$3:$J$18,5,FALSE) -> 240 | G40: =CONCATENATE(Resultados!AG73,":",Resultados!AH73) -> 4:20 | H40: =Resultados!AJ73 -> 0 | I40: =Resultados!AI73 -> -16 | J40: =Resultados!AK73 -> 6 | R40: 38° | S40: =Orden!K41 -> Norbey Flórez | T40: =Orden!L41 -> Konami | U40: =Orden!M41 -> 2 | W40: 38° | X40: =Orden!P41 | Y40: =Orden!Q41 | Z40: =Orden!R41 | AB40: 38° | AC40: =Orden!U41 | AD40: =Orden!V41 | AE40: =Orden!W41
...

Sheet Los Amigos
A1: =Equipos!B3 -> Los Amigos | H1: Fecha 1 | L1: Fecha 2 | P1: Fecha 3 | T1: Fecha 4 | X1: Fecha 5 | AB1: Fecha 6 | AF1: Fecha 7 | AJ1: Fecha 8 | AN1: Fecha 9 | AR1: Fecha 10 | AV1: Fecha 11 | AZ1: Fecha 12 | BD1: Fecha 13 | BH1: Fecha 14 | BL1: Fecha 15 | BP1: Fecha 16 | BT1: Fecha 17 | BX1: Fecha 18 | CB1: Fecha 19 | CF1: Fecha 20 | CJ1: Fecha 21 | CN1: Fecha 22 | CR1: Fecha 23 | CV1: Fecha 24 | CZ1: Fecha 25
D2: Adversario | H2: =+_xlfn.XLOOKUP($A$1,Fixture!$D$2:$D$9,Fixture!$F$2:$F$9,_xlfn.XLOOKUP($A$1,Fixture!$F$2:$F$9,Fixture!$D$2:$D$9,"Descansa",FALSE)) -> La Nueva Era | L2: =+_xlfn.XLOOKUP($A$1,Fixture!$D$10:$D$17,Fixture!$F$10:$F$17,_xlfn.XLOOKUP($A$1,Fixture!$F$10:$F$17,Fixture!$D$10:$D$17,"Descansa",FALSE)) -> La Amistad | P2: =+_xlfn.XLOOKUP($A$1,Fixture!$D$18:$D$25,Fixture!$F$18:$F$25,_xlfn.XLOOKUP($A$1,Fixture!$F$18:$F$25,Fixture!$D$18:$D$25,"Descansa",FALSE)) -> Atalanta | T2: =+_xlfn.XLOOKUP($A$1,Fixture!$D$26:$D$33,Fixture!$F$26:$F$33,_xlfn.XLOOKUP($A$1,Fixture!$F$26:$F$33,Fixture!$D$26:$D$33,"Descansa",FALSE)) -> Villanueva | X2: =+_xlfn.XLOOKUP($A$1,Fixture!$D$34:$D$41,Fixture!$F$34:$F$41,_xlfn.XLOOKUP($A$1,Fixture!$F$34:$F$41,Fixture!$D$34:$D$41,"Descansa",FALSE)) -> Ron Star | AB2: =+_xlfn.XLOOKUP($A$1,Fixture!$D$42:$D$49,Fixture!$F$42:$F$49,_xlfn.XLOOKUP($A$1,Fixture!$F$42:$F$49,Fixture!$D$42:$D$49,"Descansa",FALSE)) -> Amenadim | AF2: =+_xlfn.XLOOKUP($A$1,Fixture!$D$50:$D$57,Fixture!$F$50:$F$57,_xlfn.XLOOKUP($A$1,Fixture!$F$50:$F$57,Fixture!$D$50:$D$57,"Descansa",FALSE)) -> Hojas Anchas | AJ2: =+_xlfn.XLOOKUP($A$1,Fixture!$D$58:$D$65,Fixture!$F$58:$F$65,_xlfn.XLOOKUP($A$1,Fixture!$F$58:$F$65,Fixture!$D$58:$D$65,"Descansa",FALSE)) -> Los Aliados | AN2: =+_xlfn.XLOOKUP($A$1,Fixture!$D$66:$D$73,Fixture!$F$66:$F$73,_xlfn.XLOOKUP($A$1,Fixture!$F$66:$F$73,Fixture!$D$66:$D$73,"Descansa",FALSE)) -> Boca Juniors | AR2: =+_xlfn.XLOOKUP($A$1,Fixture!$D$74:$D$81,Fixture!$F$74:$F$81,_xlfn.XLOOKUP($A$1,Fixture!$F$74:$F$81,Fixture!$D$74:$D$81,"Descansa",FALSE)) -> Deportivo Fénix | AV2: =+_xlfn.XLOOKUP($A$1,Fixture!$D$82:$D$89,Fixture!$F$82:$F$89,_xlfn.XLOOKUP($A$1,Fixture!$F$82:$F$89,Fixture!$D$82:$D$89,"Descansa",FALSE)) -> Rayos FC | AZ2: =+_xlfn.XLOOKUP($A$1,Fixture!$D$90:$D$97,Fixture!$F$90:$F$97,_xlfn.XLOOKUP($A$1,Fixture!$F$90:$F$97,Fixture!$D$90:$D$97,"Descansa",FALSE)) -> La Unión FC | BD2: =+_xlfn.XLOOKUP($A$1,Fixture!$D$98:$D$105,Fixture!$F$98:$F$105,_xlfn.XLOOKUP($A$1,Fixture!$F$98:$F$105,Fixture!$D$98:$D$105,"Descansa",FALSE)) -> CD El Corozo | BH2: =+_xlfn.XLOOKUP($A$1,Fixture!$D$106:$D$113,Fixture!$F$106:$F$113,_xlfn.XLOOKUP($A$1,Fixture!$F$106:$F$113,Fixture!$D$106:$D$113,"Descansa",FALSE)) -> Konami | BL2: =+_xlfn.XLOOKUP($A$1,Fixture!$D$114:$D$121,Fixture!$F$114:$F$121,_xlfn.XLOOKUP($A$1,Fixture!$F$114:$F$121,Fixture!$D$114:$D$121,"Descansa",FALSE)) -> Valentín FC | BP2: =+_xlfn.XLOOKUP($A$1,Fixture!$D$122:$D$128,Fixture!$F$122:$F$128,_xlfn.XLOOKUP($A$1,Fixture!$F$122:$F$128,Fixture!$D$122:$D$128,"Descansa",FALSE)) -> Valentín FC | BT2: =+_xlfn.XLOOKUP($A$1,Fixture!$D$129:$D$135,Fixture!$F$129:$F$135,_xlfn.XLOOKUP($A$1,Fixture!$F$129:$F$135,Fixture!$D$129:$D$135,"Descansa",FALSE)) -> La Unión FC | BX2: =+_xlfn.XLOOKUP($A$1,Fixture!$D$136:$D$141,Fixture!$F$136:$F$141,_xlfn.XLOOKUP($A$1,Fixture!$F$136:$F$141,Fixture!$D$136:$D$141,"Descansa",FALSE)) -> Boca Juniors | CB2: =+_xlfn.XLOOKUP($A$1,Fixture!$D$142:$D$149,Fixture!$F$142:$F$149,_xlfn.XLOOKUP($A$1,Fixture!$F$142:$F$149,Fixture!$D$142:$D$149,"Descansa",FALSE)) -> Los Aliados | CF2: =+_xlfn.XLOOKUP($A$1,Fixture!$D$150:$D$155,Fixture!$F$150:$F$155,_xlfn.XLOOKUP($A$1,Fixture!$F$150:$F$155,Fixture!$D$150:$D$155,"Descansa",FALSE)) -> Atalanta | CJ2: =+_xlfn.XLOOKUP($A$1,Fixture!$D$156:$D$161,Fixture!$F$156:$F$161,_xlfn.XLOOKUP($A$1,Fixture!$F$156:$F$161,Fixture!$D$156:$D$161,"Descansa",FALSE)) -> Ron Star | CN2: =+_xlfn.XLOOKUP($A$1,Fixture!$D$162:$D$167,Fixture!$F$162:$F$167,_xlfn.XLOOKUP($A$1,Fixture!$F$162:$F$167,Fixture!$D$162:$D$167,"Descansa",FALSE)) -> Hojas Anchas | CR2: =+_xlfn.XLOOKUP($A$1,Fixture!$D$168:$D$169,Fixture!$F$168:$F$169,_xlfn.XLOOKUP($A$1,Fixture!$F$168:$F$169,Fixture!$D$168:$D$169,"Descanssa",FALSE)) -> Descanssa | CV2: =+_xlfn.XLOOKUP($A$1,Fixture!$D$170:$D$171,Fixture!$F$170:$F$171,_xlfn.XLOOKUP($A$1,Fixture!$F$170:$F$171,Fixture!$D$170:$D$171,"Descansa",FALSE)) -> Descansa
D3: Gol | E3: A | F3: 2A | G3: R | H3: =IF(Fixture!$C9=0,"",Fixture!$C9) -> 45809 | L3: =IF(Fixture!$C14=0,"",Fixture!$C14) -> 45683 | P3: =IF(Fixture!$C20=0,"",Fixture!$C20) -> 45690 | T3: =IF(Fixture!$C29=0,"",Fixture!$C29) -> 45697 | X3: =IF(Fixture!$C38=0,"",Fixture!$C38) -> 45704 | AB3: =IF(Fixture!$C45=0,"",Fixture!$C45) -> 45711 | AF3: =IF(Fixture!$C54=0,"",Fixture!$C54) -> 45718 | AJ3: =IF(Fixture!$C60=0,"",Fixture!$C60) -> 45725 | AN3: =IF(Fixture!$C68=0,"",Fixture!$C68) -> 45704 | AR3: =IF(Fixture!$C75=0,"",Fixture!$C75) -> 45746 | AV3: =IF(Fixture!$C83=0,"",Fixture!$C83) -> 45753 | AZ3: =IF(Fixture!$C90=0,"",Fixture!$C90) -> 45774 | BD3: =IF(Fixture!$C98=0,"",Fixture!$C98) -> 45781 | BH3: =+VLOOKUP(BH1,Resultados!$A$3:$B$71,2,FALSE) -> #N/A | BL3: =+VLOOKUP(BL1,Resultados!$A$3:$B$71,2,FALSE) -> #N/A | BP3: =+VLOOKUP(BP1,Resultados!$A$3:$B$71,2,FALSE) -> #N/A | BT3: =+VLOOKUP(BT1,Resultados!$A$3:$B$71,2,FALSE) -> #N/A | BX3: =+VLOOKUP(BX1,Resultados!$A$3:$B$71,2,FALSE) -> #N/A | CB3: =+VLOOKUP(CB1,Resultados!$A$3:$B$71,2,FALSE) -> #N/A | CF3: =+VLOOKUP(CF1,Resultados!$A$3:$B$71,2,FALSE) -> #N/A | CJ3: =+VLOOKUP(CJ1,Resultados!$A$3:$B$71,2,FALSE) -> #N/A | CN3: =+VLOOKUP(CN1,Resultados!$A$3:$B$71,2,FALSE) -> #N/A | CR3: =+VLOOKUP(CR1,Resultados!$A$3:$B$71,2,FALSE) -> #N/A | CV3: =+VLOOKUP(CV1,Resultados!$A$3:$B$71,2,FALSE) -> #N/A | CZ3: =+VLOOKUP(CZ1,Resultados!$A$3:$B$71,2,FALSE) -> #N/A
A4: Jugador | B4: =Jugadores!A3 -> Cristián Álzate | D4: =H4+L4+P4+T4+X4+AB4+AF4+AJ4+AN4+AR4+AV4+AZ4+BD4+BH4+BL4+BP4+BT4+BX4+CB4+CF4+CJ4+CN4+CR4+CV4+CZ4 -> 8 | E4: =I4+M4+Q4+U4+Y4+AC4+AG4+AK4+AO4+AS4+AW4+BA4+BE4+BI4+BM4+BQ4+BV4+BY4+CD4+CG4+CL4+CO4+CT4+CW4+DB4 -> 2 | F4: =J4+N4+R4+V4+Z4+AD4+AH4+AL4+AP4+AT4+AX4+BB4+BF4+BJ4+BN4+BT4+BX4+CB4+CF4+CJ4+CN4+CR4+CV4+CZ4 -> 5 | G4: =K4+O4+S4+W4+AA4+AE4+AI4+AM4+AQ4+AU4+AY4+BC4+BG4+BK4+BO4+BV4+BY4+CD4+CG4+CL4+CO4+CT4+CW4+DB4 -> 0 | L4: 1 | AB4: 1 | BI4: 1 | BM4: 1 | BP4: 1 | BX4: 1 | CF4: 3 | CK4: 1 | CV4: 1
B5: =Jugadores!A4 -> Germán Arenas | D5: =H5+L5+P5+T5+X5+AB5+AF5+AJ5+AN5+AR5+AV5+AZ5+BD5+BH5+BL5+BP5+BT5+BX5+CB5+CF5+CJ5+CN5+CR5+CV5+CZ5 -> 14 | E5: =I5+M5+Q5+U5+Y5+AC5+AG5+AK5+AO5+AS5+AW5+BA5+BE5+BI5+BM5+BQ5+BV5+BY5+CD5+CG5+CL5+CO5+CT5+CW5+DB5 -> 0 | F5: =J5+N5+R5+V5+Z5+AD5+AH5+AL5+AP5+AT5+AX5+BB5+BF5+BJ5+BN5+BT5+BX5+CB5+CF5+CJ5+CN5+CR5+CV5+CZ5 -> 4 | G5: =K5+O5+S5+W5+AA5+AE5+AI5+AM5+AQ5+AU5+AY5+BC5+BG5+BK5+BO5+BV5+BY5+CD5+CG5+CL5+CO5+CT5+CW5+DB5 -> 0 | L5: 3 | P5: 1 | T5: 2 | AF5: 2 | AN5: 1 | AR5: 1 | CB5: 1 | CN5: 1 | CR5: 2
B6: =Jugadores!A5 -> Juan Felipe Rincón | D6: =H6+L6+P6+T6+X6+AB6+AF6+AJ6+AN6+AR6+AV6+AZ6+BD6+BH6+BL6+BP6+BT6+BX6+CB6+CF6+CJ6+CN6+CR6+CV6+CZ6 -> 4 | E6: =I6+M6+Q6+U6+Y6+AC6+AG6+AK6+AO6+AS6+AW6+BA6+BE6+BI6+BM6+BQ6+BV6+BY6+CD6+CG6+CL6+CO6+CT6+CW6+DB6 -> 1 | F6: =J6+N6+R6+V6+Z6+AD6+AH6+AL6+AP6+AT6+AX6+BB6+BF6+BJ6+BN6+BT6+BX6+CB6+CF6+CJ6+CN6+CR6+CV6+CZ6 -> 1 | G6: =K6+O6+S6+W6+AA6+AE6+AI6+AM6+AQ6+AU6+AY6+BC6+BG6+BK6+BO6+BV6+BY6+CD6+CG6+CL6+CO6+CT6+CW6+DB6 -> 0 | M6: 1 | P6: 1 | AB6: 1 | AF6: 1 | BX6: 1
B7: =Jugadores!A6 -> Santiago Cardona | D7: =H7+L7+P7+T7+X7+AB7+AF7+AJ7+AN7+AR7+AV7+AZ7+BD7+BH7+BL7+BP7+BT7+BX7+CB7+CF7+CJ7+CN7+CR7+CV7+CZ7 -> 3 | E7: =I7+M7+Q7+U7+Y7+AC7+AG7+AK7+AO7+AS7+AW7+BA7+BE7+BI7+BM7+BQ7+BV7+BY7+CD7+CG7+CL7+CO7+CT7+CW7+DB7 -> 2 | F7: =J7+N7+R7+V7+Z7+AD7+AH7+AL7+AP7+AT7+AX7+BB7+BF7+BJ7+BN7+BT7+BX7+CB7+CF7+CJ7+CN7+CR7+CV7+CZ7 -> 2 | G7: =K7+O7+S7+W7+AA7+AE7+AI7+AM7+AQ7+AU7+AY7+BC7+BG7+BK7+BO7+BV7+BY7+CD7+CG7+CL7+CO7+CT7+CW7+DB7 -> 0 | H7: 1 | AC7: 1 | AS7: 1 | CB7: 2
B8: =Jugadores!A7 -> Héctor Iván Castrillón Hernández | D8: =H8+L8+P8+T8+X8+AB8+AF8+AJ8+AN8+AR8+AV8+AZ8+BD8+BH8+BL8+BP8+BT8+BX8+CB8+CF8+CJ8+CN8+CR8+CV8+CZ8 -> 3 | E8: =I8+M8+Q8+U8+Y8+AC8+AG8+AK8+AO8+AS8+AW8+BA8+BE8+BI8+BM8+BQ8+BV8+BY8+CD8+CG8+CL8+CO8+CT8+CW8+DB8 -> 0 | F8: =J8+N8+R8+V8+Z8+AD8+AH8+AL8+AP8+AT8+AX8+BB8+BF8+BJ8+BN8+BT8+BX8+CB8+CF8+CJ8+CN8+CR8+CV8+CZ8 -> 1 | G8: =K8+O8+S8+W8+AA8+AE8+AI8+AM8+AQ8+AU8+AY8+BC8+BG8+BK8+BO8+BV8+BY8+CD8+CG8+CL8+CO8+CT8+CW8+DB8 -> 0 | P8: 2 | CR8: 1 | CS8: 1
B9: =Jugadores!A8 -> Sebastián Sepulveda | D9: =H9+L9+P9+T9+X9+AB9+AF9+AJ9+AN9+AR9+AV9+AZ9+BD9+BH9+BL9+BP9+BT9+BX9+CB9+CF9+CJ9+CN9+CR9+CV9+CZ9 -> 10 | E9: =I9+M9+Q9+U9+Y9+AC9+AG9+AK9+AO9+AS9+AW9+BA9+BE9+BI9+BM9+BQ9+BV9+BY9+CD9+CG9+CL9+CO9+CT9+CW9+DB9 -> 1 | F9: =J9+N9+R9+V9+Z9+AD9+AH9+AL9+AP9+AT9+AX9+BB9+BF9+BJ9+BN9+BT9+BX9+CB9+CF9+CJ9+CN9+CR9+CV9+CZ9 -> 1 | G9: =K9+O9+S9+W9+AA9+AE9+AI9+AM9+AQ9+AU9+AY9+BC9+BG9+BK9+BO9+BV9+BY9+CD9+CG9+CL9+CO9+CT9+CW9+DB9 -> 1 | H9: 1 | L9: 1 | P9: 1 | X9: 2 | AF9: 1 | AZ9: 1 | BL9: 1 | BP9: 1 | BT9: 1 | BU9: 1 | BY9: 1 | CS9: 1
B10: =Jugadores!A9 -> Daniel Ossa | D10: =H10+L10+P10+T10+X10+AB10+AF10+AJ10+AN10+AR10+AV10+AZ10+BD10+BH10+BL10+BP10+BT10+BX10+CB10+CF10+CJ10+CN10+CR10+CV10+CZ10 -> 10 | E10: =I10+M10+Q10+U10+Y10+AC10+AG10+AK10+AO10+AS10+AW10+BA10+BE10+BI10+BM10+BQ10+BV10+BY10+CD10+CG10+CL10+CO10+CT10+CW10+DB10 -> 4 | F10: =J10+N10+R10+V10+Z10+AD10+AH10+AL10+AP10+AT10+AX10+BB10+BF10+BJ10+BN10+BT10+BX10+CB10+CF10+CJ10+CN10+CR10+CV10+CZ10 -> 5 | G10: =K10+O10+S10+W10+AA10+AE10+AI10+AM10+AQ10+AU10+AY10+BC10+BG10+BK10+BO10+BV10+BY10+CD10+CG10+CL10+CO10+CT10+CW10+DB10 -> 0 | H10: 1 | P10: 2 | U10: 1 | AB10: 1 | AG10: 1 | AZ10: 1 | BA10: 1 | BM10: 1 | CB10: 2 | CF10: 3
B11: =Jugadores!A10 -> Diego Castrillón | D11: =H11+L11+P11+T11+X11+AB11+AF11+AJ11+AN11+AR11+AV11+AZ11+BD11+BH11+BL11+BP11+BT11+BX11+CB11+CF11+CJ11+CN11+CR11+CV11+CZ11 -> 3 | E11: =I11+M11+Q11+U11+Y11+AC11+AG11+AK11+AO11+AS11+AW11+BA11+BE11+BI11+BM11+BQ11+BV11+BY11+CD11+CG11+CL11+CO11+CT11+CW11+DB11 -> 2 | F11: =J11+N11+R11+V11+Z11+AD11+AH11+AL11+AP11+AT11+AX11+BB11+BF11+BJ11+BN11+BT11+BX11+CB11+CF11+CJ11+CN11+CR11+CV11+CZ11 -> 0 | G11: =K11+O11+S11+W11+AA11+AE11+AI11+AM11+AQ11+AU11+AY11+BC11+BG11+BK11+BO11+BV11+BY11+CD11+CG11+CL11+CO11+CT11+CW11+DB11 -> 1 | U11: 1 | X11: 1 | AN11: 1 | AR11: 1 | CO11: 1
B12: =Jugadores!A11 -> Hernán Sánchez | D12: =H12+L12+P12+T12+X12+AB12+AF12+AJ12+AN12+AR12+AV12+AZ12+BD12+BH12+BL12+BP12+BT12+BX12+CB12+CF12+CJ12+CN12+CR12+CV12+CZ12 -> 30 | E12: =I12+M12+Q12+U12+Y12+AC12+AG12+AK12+AO12+AS12+AW12+BA12+BE12+BI12+BM12+BQ12+BV12+BY12+CD12+CG12+CL12+CO12+CT12+CW12+DB12 -> 2 | F12: =J12+N12+R12+V12+Z12+AD12+AH12+AL12+AP12+AT12+AX12+BB12+BF12+BJ12+BN12+BT12+BX12+CB12+CF12+CJ12+CN12+CR12+CV12+CZ12 -> 5 | G12: =K12+O12+S12+W12+AA12+AE12+AI12+AM12+AQ12+AU12+AY12+BC12+BG12+BK12+BO12+BV12+BY12+CD12+CG12+CL12+CO12+CT12+CW12+DB12 -> 0 | H12: 6 | L12: 1 | T12: 1 | X12: 1 | AB12: 3 | AC12: 1 | AJ12: 1 | AR12: 4 | AZ12: 3 | BD12: 3 | BH12: 1 | BL12: 1 | BN12: 1 | BP12: 1 | BQ12: 1 | BT12: 2 | BX12: 2
B13: =Jugadores!A12 -> Juan Felipe Castro | D13: =H13+L13+P13+T13+X13+AB13+AF13+AJ13+AN13+AR13+AV13+AZ13+BD13+BH13+BL13+BP13+BT13+BX13+CB13+CF13+CJ13+CN13+CR13+CV13+CZ13 -> 0 | E13: =I13+M13+Q13+U13+Y13+AC13+AG13+AK13+AO13+AS13+AW13+BA13+BE13+BI13+BM13+BQ13+BV13+BY13+CD13+CG13+CL13+CO13+CT13+CW13+DB13 -> 0 | F13: =J13+N13+R13+V13+Z13+AD13+AH13+AL13+AP13+AT13+AX13+BB13+BF13+BJ13+BN13+BT13+BX13+CB13+CF13+CJ13+CN13+CR13+CV13+CZ13 -> 0 | G13: =K13+O13+S13+W13+AA13+AE13+AI13+AM13+AQ13+AU13+AY13+BC13+BG13+BK13+BO13+BV13+BY13+CD13+CG13+CL13+CO13+CT13+CW13+DB13 -> 1 | W13: 1
B14: =Jugadores!A13 -> Jhon Restrepo | D14: =H14+L14+P14+T14+X14+AB14+AF14+AJ14+AN14+AR14+AV14+AZ14+BD14+BH14+BL14+BP14+BT14+BX14+CB14+CF14+CJ14+CN14+CR14+CV14+CZ14 -> 6 | E14: =I14+M14+Q14+U14+Y14+AC14+AG14+AK14+AO14+AS14+AW14+BA14+BE14+BI14+BM14+BQ14+BV14+BY14+CD14+CG14+CL14+CO14+CT14+CW14+DB14 -> 3 | F14: =J14+N14+R14+V14+Z14+AD14+AH14+AL14+AP14+AT14+AX14+BB14+BF14+BJ14+BN14+BT14+BX14+CB14+CF14+CJ14+CN14+CR14+CV14+CZ14 -> 4 | G14: =K14+O14+S14+W14+AA14+AE14+AI14+AM14+AQ14+AU14+AY14+BC14+BG14+BK14+BO14+BV14+BY14+CD14+CG14+CL14+CO14+CT14+CW14+DB14 -> 0 | Y14: 1 | AC14: 1 | AK14: 1 | AN14: 2 | CC14: 1 | CF14: 2 | CJ14: 1 | CK14: 1 | CN14: 1
B15: =Jugadores!A14 -> Juan Felipe Hincapié | D15: =H15+L15+P15+T15+X15+AB15+AF15+AJ15+AN15+AR15+AV15+AZ15+BD15+BH15+BL15+BP15+BT15+BX15+CB15+CF15+CJ15+CN15+CR15+CV15+CZ15 -> 2 | E15: =I15+M15+Q15+U15+Y15+AC15+AG15+AK15+AO15+AS15+AW15+BA15+BE15+BI15+BM15+BQ15+BV15+BY15+CD15+CG15+CL15+CO15+CT15+CW15+DB15 -> 0 | F15: =J15+N15+R15+V15+Z15+AD15+AH15+AL15+AP15+AT15+AX15+BB15+BF15+BJ15+BN15+BT15+BX15+CB15+CF15+CJ15+CN15+CR15+CV15+CZ15 -> 2 | G15: =K15+O15+S15+W15+AA15+AE15+AI15+AM15+AQ15+AU15+AY15+BC15+BG15+BK15+BO15+BV15+BY15+CD15+CG15+CL15+CO15+CT15+CW15+DB15 -> 0 | CB15: 2
B16: =Jugadores!A15 -> Juan Felipe Ayala | D16: =H16+L16+P16+T16+X16+AB16+AF16+AJ16+AN16+AR16+AV16+AZ16+BD16+BH16+BL16+BP16+BT16+BX16+CB16+CF16+CJ16+CN16+CR16+CV16+CZ16 -> 2 | E16: =I16+M16+Q16+U16+Y16+AC16+AG16+AK16+AO16+AS16+AW16+BA16+BE16+BI16+BM16+BQ16+BV16+BY16+CD16+CG16+CL16+CO16+CT16+CW16+DB16 -> 0 | F16: =J16+N16+R16+V16+Z16+AD16+AH16+AL16+AP16+AT16+AX16+BB16+BF16+BJ16+BN16+BT16+BX16+CB16+CF16+CJ16+CN16+CR16+CV16+CZ16 -> 1 | G16: =K16+O16+S16+W16+AA16+AE16+AI16+AM16+AQ16+AU16+AY16+BC16+BG16+BK16+BO16+BV16+BY16+CD16+CG16+CL16+CO16+CT16+CW16+DB16 -> 0 | BP16: 1 | BU16: 1 | CB16: 1
B17: =Jugadores!A16 -> Santiago Quiroz | D17: =H17+L17+P17+T17+X17+AB17+AF17+AJ17+AN17+AR17+AV17+AZ17+BD17+BH17+BL17+BP17+BT17+BX17+CB17+CF17+CJ17+CN17+CR17+CV17+CZ17 -> 7 | E17: =I17+M17+Q17+U17+Y17+AC17+AG17+AK17+AO17+AS17+AW17+BA17+BE17+BI17+BM17+BQ17+BV17+BY17+CD17+CG17+CL17+CO17+CT17+CW17+DB17 -> 1 | F17: =J17+N17+R17+V17+Z17+AD17+AH17+AL17+AP17+AT17+AX17+BB17+BF17+BJ17+BN17+BT17+BX17+CB17+CF17+CJ17+CN17+CR17+CV17+CZ17 -> 4 | G17: =K17+O17+S17+W17+AA17+AE17+AI17+AM17+AQ17+AU17+AY17+BC17+BG17+BK17+BO17+BV17+BY17+CD17+CG17+CL17+CO17+CT17+CW17+DB17 -> 0 | AF17: 2 | AR17: 1 | AS17: 1 | CN17: 2 | CR17: 1 | CV17: 1
B18: =Jugadores!A17 -> John Walter Restrepo | D18: =H18+L18+P18+T18+X18+AB18+AF18+AJ18+AN18+AR18+AV18+AZ18+BD18+BH18+BL18+BP18+BT18+BX18+CB18+CF18+CJ18+CN18+CR18+CV18+CZ18 -> 0 | E18: =I18+M18+Q18+U18+Y18+AC18+AG18+AK18+AO18+AS18+AW18+BA18+BE18+BI18+BM18+BQ18+BV18+BY18+CD18+CG18+CL18+CO18+CT18+CW18+DB18 -> 1 | F18: =J18+N18+R18+V18+Z18+AD18+AH18+AL18+AP18+AT18+AX18+BB18+BF18+BJ18+BN18+BT18+BX18+CB18+CF18+CJ18+CN18+CR18+CV18+CZ18 -> 0 | G18: =K18+O18+S18+W18+AA18+AE18+AI18+AM18+AQ18+AU18+AY18+BC18+BG18+BK18+BO18+BV18+BY18+CD18+CG18+CL18+CO18+CT18+CW18+DB18 -> 0 | BQ18: 1
B19: Autogoles a favor
B20: Goles por OW | AV20: 3
B21: Gol por jugador Retirado
D22: =H22+L22+P22+T22+X22+AB22+AF22+AJ22+AN22+AR22+AV22+AZ22+BD22+BH22+BL22+BP22+BT22+BX22+CB22+CF22+CJ22+CN22+CR22+CV22+CZ22 -> 105 | E22: =I22+M22+Q22+U22+Y22+AC22+AG22+AK22+AO22+AS22+AW22+BA22+BE22+BI22+BM22+BQ22+BV22+BY22+CD22+CG22+CL22+CO22+CT22+CW22+DB22 -> 19 | F22: =J22+N22+R22+V22+Z22+AD22+AH22+AL22+AP22+AT22+AX22+BB22+BF22+BJ22+BN22+BT22+BX22+CB22+CF22+CJ22+CN22+CR22+CV22+CZ22 -> 35 | G22: =K22+O22+S22+W22+AA22+AE22+AI22+AM22+AQ22+AU22+AY22+BC22+BG22+BK22+BO22+BV22+BY22+CD22+CG22+CL22+CO22+CT22+CW22+DB22 -> 3 | H22: =SUM(H4:H21) -> 9 | I22: =SUM(I4:I18) -> 0 | J22: =SUM(J4:J18) -> 0 | K22: =SUM(K4:K20) -> 0 | L22: =SUM(L4:L21) -> 6 | M22: =SUM(M4:M18) -> 1 | N22: =SUM(N4:N18) -> 0 | O22: =SUM(O4:O20) -> 0 | P22: =SUM(P4:P21) -> 7 | Q22: =SUM(Q4:Q18) -> 0 | R22: =SUM(R4:R18) -> 0 | S22: =SUM(S4:S20) -> 0 | T22: =SUM(T4:T21) -> 3 | U22: =SUM(U4:U18) -> 2 | V22: =SUM(V4:V18) -> 0 | W22: =SUM(W4:W20) -> 1 | X22: =SUM(X4:X21) -> 4 | Y22: =SUM(Y4:Y18) -> 1 | Z22: =SUM(Z4:Z18) -> 0 | AA22: =SUM(AA4:AA20) -> 0 | AB22: =SUM(AB4:AB21) -> 6 | AC22: =SUM(AC4:AC18) -> 3 | AD22: =SUM(AD4:AD18) -> 0 | AE22: =SUM(AE4:AE20) -> 0 | AF22: =SUM(AF4:AF21) -> 6 | AG22: =SUM(AG4:AG18) -> 1 | AH22: =SUM(AH4:AH18) -> 0 | AI22: =SUM(AI4:AI20) -> 0 | AJ22: =SUM(AJ4:AJ21) -> 1 | AK22: =SUM(AK4:AK18) -> 1 | AL22: =SUM(AL4:AL18) -> 0 | AM22: =SUM(AM4:AM20) -> 0 | AN22: =SUM(AN4:AN21) -> 4 | AO22: =SUM(AO4:AO18) -> 0 | AP22: =SUM(AP4:AP18) -> 0 | AQ22: =SUM(AQ4:AQ20) -> 0 | AR22: =SUM(AR4:AR21) -> 7 | AS22: =SUM(AS4:AS18) -> 2 | AT22: =SUM(AT4:AT18) -> 0 | AU22: =SUM(AU4:AU20) -> 0 | AV22: =SUM(AV4:AV21) -> 3 | AW22: =SUM(AW4:AW18) -> 0 | AX22: =SUM(AX4:AX18) -> 0 | AY22: =SUM(AY4:AY20) -> 0 | AZ22: =SUM(AZ4:AZ21) -> 5 | BA22: =SUM(BA4:BA18) -> 1 | BB22: =SUM(BB4:BB18) -> 0 | BC22: =SUM(BC4:BC20) -> 0 | BD22: =SUM(BD4:BD21) -> 3 | BE22: =SUM(BE4:BE18) -> 0 | BF22: =SUM(BF4:BF18) -> 0 | BG22: =SUM(BG4:BG20) -> 0 | BH22: =SUM(BH4:BH21) -> 1 | BI22: =SUM(BI4:BI18) -> 1 | BJ22: =SUM(BJ4:BJ18) -> 0 | BK22: =SUM(BK4:BK20) -> 0 | BL22: =SUM(BL4:BL21) -> 2 | BM22: =SUM(BM4:BM18) -> 2 | BN22: =SUM(BN4:BN18) -> 1 | BO22: =SUM(BO4:BO20) -> 0 | BP22: =SUM(BP4:BP21) -> 4 | BQ22: =SUM(BQ4:BQ18) -> 2 | BR22: =SUM(BR4:BR18) -> 0 | BS22: =SUM(BS4:BS20) -> 0 | BT22: =SUM(BT4:BT21) -> 3 | BU22: =SUM(BU4:BU18) -> 2 | BV22: =SUM(BV4:BV18) -> 0 | BW22: =SUM(BW4:BW20) -> 0 | BX22: =SUM(BX4:BX21) -> 4 | BY22: =SUM(BY4:BY18) -> 1 | BZ22: =SUM(BZ4:BZ18) -> 0 | CA22: =SUM(CA4:CA20) -> 0 | CB22: =SUM(CB4:CB21) -> 8 | CC22: =SUM(CC4:CC18) -> 1 | CD22: =SUM(CD4:CD18) -> 0 | CE22: =SUM(CE4:CE20) -> 0 | CF22: =SUM(CF4:CF21) -> 8 | CG22: =SUM(CG4:CG18) -> 0 | CH22: =SUM(CH4:CH18) -> 0 | CI22: =SUM(CI4:CI20) -> 0 | CJ22: =SUM(CJ4:CJ21) -> 1 | CK22: =SUM(CK4:CK18) -> 2 | CL22: =SUM(CL4:CL18) -> 0 | CM22: =SUM(CM4:CM20) -> 0 | CN22: =SUM(CN4:CN21) -> 4 | CO22: =SUM(CO4:CO18) -> 1 | CP22: =SUM(CP4:CP18) -> 0 | CQ22: =SUM(CQ4:CQ20) -> 0 | CR22: =SUM(CR4:CR21) -> 4 | CS22: =SUM(CS4:CS18) -> 2 | CT22: =SUM(CT4:CT18) -> 0 | CU22: =SUM(CU4:CU20) -> 0 | CV22: =SUM(CV4:CV21) -> 2 | CW22: =SUM(CW4:CW18) -> 0 | CX22: =SUM(CX4:CX18) -> 0 | CY22: =SUM(CY4:CY20) -> 0 | CZ22: =SUM(CZ4:CZ21) -> 0 | DA22: =SUM(DA4:DA18) -> 0 | DB22: =SUM(DB4:DB18) -> 0 | DC22: =SUM(DC4:DC20) -> 0
D23: Total Goles | E23: Total A | F23: Total 2A | G23: Total R | H23: Total Goles | I23: Total A | J23: Total 2A | K23: Total R | L23: Total Goles | M23: Total A | N23: Total 2A | O23: Total R | P23: Total Goles | Q23: Total A | R23: Total 2A | S23: Total R | T23: Total Goles | U23: Total A | V23: Total 2A | W23: Total R | X23: Total Goles | Y23: Total A | Z23: Total 2A | AA23: Total R | AB23: Total Goles | AC23: Total A | AD23: Total 2A | AE23: Total R | AF23: Total Goles | AG23: Total A | AH23: Total 2A | AI23: Total R | AJ23: Total Goles | AK23: Total A | AL23: Total 2A | AM23: Total R | AN23: Total Goles | AO23: Total A | AP23: Total 2A | AQ23: Total R | AR23: Total Goles | AS23: Total A | AT23: Total 2A | AU23: Total R | AV23: Total Goles | AW23: Total A | AX23: Total 2A | AY23: Total R | AZ23: Total Goles | BA23: Total A | BB23: Total 2A | BC23: Total R | BD23: Total Goles | BE23: Total A | BF23: Total 2A | BG23: Total R | BH23: Total Goles | BI23: Total A | BJ23: Total 2A | BK23: Total R | BL23: Total Goles | BM23: Total A | BN23: Total 2A | BO23: Total R | BP23: Total Goles | BQ23: Total A | BR23: Total 2A | BS23: Total R | BT23: Total Goles | BU23: Total A | BV23: Total 2A | BW23: Total R | BX23: Total Goles | BY23: Total A | BZ23: Total 2A | CA23: Total R | CB23: Total Goles | CC23: Total A | CD23: Total 2A | CE23: Total R | CF23: Total Goles | CG23: Total A | CH23: Total 2A | CI23: Total R | CJ23: Total Goles | CK23: Total A | CL23: Total 2A | CM23: Total R | CN23: Total Goles | CO23: Total A | CP23: Total 2A | CQ23: Total R | CR23: Total Goles | CS23: Total A | CT23: Total 2A | CU23: Total R | CV23: Total Goles | CW23: Total A | CX23: Total 2A | CY23: Total R | CZ23: Total Goles | DA23: Total A | DB23: Total 2A | DC23: Total R

Sheet La Nueva Era
A1: =Equipos!B4 -> La Nueva Era | H1: Fecha 1 | L1: Fecha 2 | P1: Fecha 3 | T1: Fecha 4 | X1: Fecha 5 | AB1: Fecha 6 | AF1: Fecha 7 | AJ1: Fecha 8 | AN1: Fecha 9 | AR1: Fecha 10 | AV1: Fecha 11 | AZ1: Fecha 12 | BD1: Fecha 13 | BH1: Fecha 14 | BL1: Fecha 15 | BP1: Fecha 16 | BT1: Fecha 17 | BX1: Fecha 18 | CB1: Fecha 19 | CF1: Fecha 20 | CJ1: Fecha 21 | CN1: Fecha 22 | CR1: Fecha 23 | CV1: Fecha 24 | CZ1: Fecha 25
D2: Adversario | H2: =+_xlfn.XLOOKUP($A$1,Fixture!$D$2:$D$9,Fixture!$F$2:$F$9,_xlfn.XLOOKUP($A$1,Fixture!$F$2:$F$9,Fixture!$D$2:$D$9,"Descansa",FALSE)) -> Los Amigos | L2: =+_xlfn.XLOOKUP($A$1,Fixture!$D$10:$D$17,Fixture!$F$10:$F$17,_xlfn.XLOOKUP($A$1,Fixture!$F$10:$F$17,Fixture!$D$10:$D$17,"Descansa",FALSE)) -> Valentín FC | P2: =+_xlfn.XLOOKUP($A$1,Fixture!$D$18:$D$25,Fixture!$F$18:$F$25,_xlfn.XLOOKUP($A$1,Fixture!$F$18:$F$25,Fixture!$D$18:$D$25,"Descansa",FALSE)) -> CD El Corozo | T2: =+_xlfn.XLOOKUP($A$1,Fixture!$D$26:$D$33,Fixture!$F$26:$F$33,_xlfn.XLOOKUP($A$1,Fixture!$F$26:$F$33,Fixture!$D$26:$D$33,"Descansa",FALSE)) -> Konami | X2: =+_xlfn.XLOOKUP($A$1,Fixture!$D$34:$D$41,Fixture!$F$34:$F$41,_xlfn.XLOOKUP($A$1,Fixture!$F$34:$F$41,Fixture!$D$34:$D$41,"Descansa",FALSE)) -> Villanueva | AB2: =+_xlfn.XLOOKUP($A$1,Fixture!$D$42:$D$49,Fixture!$F$42:$F$49,_xlfn.XLOOKUP($A$1,Fixture!$F$42:$F$49,Fixture!$D$42:$D$49,"Descansa",FALSE)) -> Ron Star | AF2: =+_xlfn.XLOOKUP($A$1,Fixture!$D$50:$D$57,Fixture!$F$50:$F$57,_xlfn.XLOOKUP($A$1,Fixture!$F$50:$F$57,Fixture!$D$50:$D$57,"Descansa",FALSE)) -> Amenadim | AJ2: =+_xlfn.XLOOKUP($A$1,Fixture!$D$58:$D$65,Fixture!$F$58:$F$65,_xlfn.XLOOKUP($A$1,Fixture!$F$58:$F$65,Fixture!$D$58:$D$65,"Descansa",FALSE)) -> Hojas Anchas | AN2: =+_xlfn.XLOOKUP($A$1,Fixture!$D$66:$D$73,Fixture!$F$66:$F$73,_xlfn.XLOOKUP($A$1,Fixture!$F$66:$F$73,Fixture!$D$66:$D$73,"Descansa",FALSE)) -> Los Aliados | AR2: =+_xlfn.XLOOKUP($A$1,Fixture!$D$74:$D$81,Fixture!$F$74:$F$81,_xlfn.XLOOKUP($A$1,Fixture!$F$74:$F$81,Fixture!$D$74:$D$81,"Descansa",FALSE)) -> Boca Juniors | AV2: =+_xlfn.XLOOKUP($A$1,Fixture!$D$82:$D$89,Fixture!$F$82:$F$89,_xlfn.XLOOKUP($A$1,Fixture!$F$82:$F$89,Fixture!$D$82:$D$89,"Descansa",FALSE)) -> Deportivo Fénix | AZ2: =+_xlfn.XLOOKUP($A$1,Fixture!$D$90:$D$97,Fixture!$F$90:$F$97,_xlfn.XLOOKUP($A$1,Fixture!$F$90:$F$97,Fixture!$D$90:$D$97,"Descansa",FALSE)) -> Rayos FC | BD2: =+_xlfn.XLOOKUP($A$1,Fixture!$D$98:$D$105,Fixture!$F$98:$F$105,_xlfn.XLOOKUP($A$1,Fixture!$F$98:$F$105,Fixture!$D$98:$D$105,"Descansa",FALSE)) -> La Unión FC | BH2: =+_xlfn.XLOOKUP($A$1,Fixture!$D$106:$D$113,Fixture!$F$106:$F$113,_xlfn.XLOOKUP($A$1,Fixture!$F$106:$F$113,Fixture!$D$106:$D$113,"Descansa",FALSE)) -> La Amistad | BL2: =+_xlfn.XLOOKUP($A$1,Fixture!$D$114:$D$121,Fixture!$F$114:$F$121,_xlfn.XLOOKUP($A$1,Fixture!$F$114:$F$121,Fixture!$D$114:$D$121,"Descansa",FALSE)) -> Atalanta | BP2: =+_xlfn.XLOOKUP($A$1,Fixture!$D$122:$D$128,Fixture!$F$122:$F$128,_xlfn.XLOOKUP($A$1,Fixture!$F$122:$F$128,Fixture!$D$122:$D$128,"Descansa",FALSE)) -> La Amistad | BT2: =+_xlfn.XLOOKUP($A$1,Fixture!$D$129:$D$135,Fixture!$F$129:$F$135,_xlfn.XLOOKUP($A$1,Fixture!$F$129:$F$135,Fixture!$D$129:$D$135,"Descansa",FALSE)) -> Deportivo Fénix | BX2: =+_xlfn.XLOOKUP($A$1,Fixture!$D$136:$D$141,Fixture!$F$136:$F$141,_xlfn.XLOOKUP($A$1,Fixture!$F$136:$F$141,Fixture!$D$136:$D$141,"Descansa",FALSE)) -> Konami | CB2: =+_xlfn.XLOOKUP($A$1,Fixture!$D$142:$D$149,Fixture!$F$142:$F$149,_xlfn.XLOOKUP($A$1,Fixture!$F$142:$F$149,Fixture!$D$142:$D$149,"Descansa",FALSE)) -> Villanueva | CF2: =+_xlfn.XLOOKUP($A$1,Fixture!$D$150:$D$155,Fixture!$F$150:$F$155,_xlfn.XLOOKUP($A$1,Fixture!$F$150:$F$155,Fixture!$D$150:$D$155,"Descansa",FALSE)) -> Descansa | CJ2: =+_xlfn.XLOOKUP($A$1,Fixture!$D$156:$D$161,Fixture!$F$156:$F$161,_xlfn.XLOOKUP($A$1,Fixture!$F$156:$F$161,Fixture!$D$156:$D$161,"Descansa",FALSE)) -> CD El Corozo | CN2: =+_xlfn.XLOOKUP($A$1,Fixture!$D$162:$D$167,Fixture!$F$162:$F$167,_xlfn.XLOOKUP($A$1,Fixture!$F$162:$F$167,Fixture!$D$162:$D$167,"Descansa",FALSE)) -> Descansa | CR2: =+_xlfn.XLOOKUP($A$1,Fixture!$D$168:$D$169,Fixture!$F$168:$F$169,_xlfn.XLOOKUP($A$1,Fixture!$F$168:$F$169,Fixture!$D$168:$D$169,"Descanssa",FALSE)) -> Descanssa | CV2: =+_xlfn.XLOOKUP($A$1,Fixture!$D$170:$D$171,Fixture!$F$170:$F$171,_xlfn.XLOOKUP($A$1,Fixture!$F$170:$F$171,Fixture!$D$170:$D$171,"Descansa",FALSE)) -> Descansa
D3: Gol | E3: A | F3: 2A | G3: R | H3: =IF(Fixture!$C4=0,"",Fixture!$C4) -> 45676 | L3: =IF(Fixture!$C12=0,"",Fixture!$C12) -> 45683 | P3: =IF(Fixture!$C23=0,"",Fixture!$C23) -> 45690 | T3: =IF(Fixture!$C27=0,"",Fixture!$C27) -> 45697 | X3: =IF(Fixture!$C35=0,"",Fixture!$C35) -> 45704 | AB3: =IF(Fixture!$C42=0,"",Fixture!$C42) -> 45711 | AF3: =IF(Fixture!$C50=0,"",Fixture!$C50) -> 45718 | AJ3: =IF(Fixture!$C65=0,"",Fixture!$C65) -> 45725 | AN3: =IF(Fixture!$C66=0,"",Fixture!$C66) -> 45704 | AR3: =IF(Fixture!$C74=0,"",Fixture!$C74) -> 45746 | AV3: =IF(Fixture!$C83=0,"",Fixture!$C83) -> 45753 | AZ3: =IF(Fixture!$C91=0,"",Fixture!$C91) -> 45774 | BD3: =IF(Fixture!$C100=0,"",Fixture!$C100) -> 45781 | BH3: =+VLOOKUP(BH1,Resultados!$A$3:$B$71,2,FALSE) -> #N/A | BL3: =+VLOOKUP(BL1,Resultados!$A$3:$B$71,2,FALSE) -> #N/A | BP3: =+VLOOKUP(BP1,Resultados!$A$3:$B$71,2,FALSE) -> #N/A | BT3: =+VLOOKUP(BT1,Resultados!$A$3:$B$71,2,FALSE) -> #N/A | BX3: =+VLOOKUP(BX1,Resultados!$A$3:$B$71,2,FALSE) -> #N/A | CB3: =+VLOOKUP(CB1,Resultados!$A$3:$B$71,2,FALSE) -> #N/A | CF3: =+VLOOKUP(CF1,Resultados!$A$3:$B$71,2,FALSE) -> #N/A | CJ3: =+VLOOKUP(CJ1,Resultados!$A$3:$B$71,2,FALSE) -> #N/A | CN3: =+VLOOKUP(CN1,Resultados!$A$3:$B$71,2,FALSE) -> #N/A | CR3: =+VLOOKUP(CR1,Resultados!$A$3:$B$71,2,FALSE) -> #N/A | CV3: =+VLOOKUP(CV1,Resultados!$A$3:$B$71,2,FALSE) -> #N/A | CZ3: =+VLOOKUP(CZ1,Resultados!$A$3:$B$71,2,FALSE) -> #N/A
A4: Jugador | B4: =Jugadores!B3 -> Jaidiver Montoya | D4: =H4+L4+P4+T4+X4+AB4+AF4+AJ4+AN4+AR4+AV4+AZ4+BD4+BH4+BL4+BP4+BT4+BX4+CB4+CF4+CJ4+CN4+CR4+CV4+CZ4 -> 7 | E4: =I4+M4+Q4+U4+Y4+AC4+AG4+AK4+AO4+AS4+AW4+BA4+BE4+BI4+BM4+BQ4+BU4+BY4+CC4+CG4+CK4+CO4+CS4+CW4+DA4 -> 1 | F4: =J4+N4+R4+V4+Z4+AD4+AH4+AL4+AP4+AT4+AX4+BB4+BF4+BJ4+BN4+BR4+BV4+BZ4+CD4+CH4+CL4+CP4+CT4+CX4 -> 0 | G4: =K4+O4+S4+W4+AA4+AE4+AI4+AM4+AQ4+AU4+AY4+BC4+BG4+BK4+BO4+BS4+BW4+CA4+CE4+CI4+CM4+CQ4+CU4+CY4 -> 0 | Q4: 1 | T4: 1 | AB4: 2 | AR4: 1 | BL4: 2 | BX4: 1
B5: =Jugadores!B4 -> Nafer Narváez | D5: =H5+L5+P5+T5+X5+AB5+AF5+AJ5+AN5+AR5+AV5+AZ5+BD5+BH5+BL5+BP5+BT5+BX5+CB5+CF5+CJ5+CN5+CR5+CV5+CZ5 -> 0 | E5: =I5+M5+Q5+U5+Y5+AC5+AG5+AK5+AO5+AS5+AW5+BA5+BE5+BI5+BM5+BQ5+BU5+BY5+CC5+CG5+CK5+CO5+CS5+CW5+DA5 -> 0 | F5: =J5+N5+R5+V5+Z5+AD5+AH5+AL5+AP5+AT5+AX5+BB5+BF5+BJ5+BN5+BR5+BV5+BZ5+CD5+CH5+CL5+CP5+CT5+CX5 -> 0 | G5: =K5+O5+S5+W5+AA5+AE5+AI5+AM5+AQ5+AU5+AY5+BC5+BG5+BK5+BO5+BS5+BW5+CA5+CE5+CI5+CM5+CQ5+CU5+CY5 -> 0
B6: =Jugadores!B5 -> Jhonatan Carvajal | D6: =H6+L6+P6+T6+X6+AB6+AF6+AJ6+AN6+AR6+AV6+AZ6+BD6+BH6+BL6+BP6+BT6+BX6+CB6+CF6+CJ6+CN6+CR6+CV6+CZ6 -> 6 | E6: =I6+M6+Q6+U6+Y6+AC6+AG6+AK6+AO6+AS6+AW6+BA6+BE6+BI6+BM6+BQ6+BU6+BY6+CC6+CG6+CK6+CO6+CS6+CW6+DA6 -> 0 | F6: =J6+N6+R6+V6+Z6+AD6+AH6+AL6+AP6+AT6+AX6+BB6+BF6+BJ6+BN6+BR6+BV6+BZ6+CD6+CH6+CL6+CP6+CT6+CX6 -> 0 | G6: =K6+O6+S6+W6+AA6+AE6+AI6+AM6+AQ6+AU6+AY6+BC6+BG6+BK6+BO6+BS6+BW6+CA6+CE6+CI6+CM6+CQ6+CU6+CY6 -> 0 | AF6: 1 | AN6: 2 | BD6: 2 | BT6: 1
B7: =Jugadores!B6 -> Gonzalo Carvajal | D7: =H7+L7+P7+T7+X7+AB7+AF7+AJ7+AN7+AR7+AV7+AZ7+BD7+BH7+BL7+BP7+BT7+BX7+CB7+CF7+CJ7+CN7+CR7+CV7+CZ7 -> 6 | E7: =I7+M7+Q7+U7+Y7+AC7+AG7+AK7+AO7+AS7+AW7+BA7+BE7+BI7+BM7+BQ7+BU7+BY7+CC7+CG7+CK7+CO7+CS7+CW7+DA7 -> 2 | F7: =J7+N7+R7+V7+Z7+AD7+AH7+AL7+AP7+AT7+AX7+BB7+BF7+BJ7+BN7+BR7+BV7+BZ7+CD7+CH7+CL7+CP7+CT7+CX7 -> 0 | G7: =K7+O7+S7+W7+AA7+AE7+AI7+AM7+AQ7+AU7+AY7+BC7+BG7+BK7+BO7+BS7+BW7+CA7+CE7+CI7+CM7+CQ7+CU7+CY7 -> 0 | AF7: 1 | AJ7: 1 | AO7: 1 | AR7: 2 | AV7: 1 | BH7: 1 | BY7: 1
B8: =Jugadores!B7 -> Alejandro Ospina | D8: =H8+L8+P8+T8+X8+AB8+AF8+AJ8+AN8+AR8+AV8+AZ8+BD8+BH8+BL8+BP8+BT8+BX8+CB8+CF8+CJ8+CN8+CR8+CV8+CZ8 -> 1 | E8: =I8+M8+Q8+U8+Y8+AC8+AG8+AK8+AO8+AS8+AW8+BA8+BE8+BI8+BM8+BQ8+BU8+BY8+CC8+CG8+CK8+CO8+CS8+CW8+DA8 -> 0 | F8: =J8+N8+R8+V8+Z8+AD8+AH8+AL8+AP8+AT8+AX8+BB8+BF8+BJ8+BN8+BR8+BV8+BZ8+CD8+CH8+CL8+CP8+CT8+CX8 -> 0 | G8: =K8+O8+S8+W8+AA8+AE8+AI8+AM8+AQ8+AU8+AY8+BC8+BG8+BK8+BO8+BS8+BW8+CA8+CE8+CI8+CM8+CQ8+CU8+CY8 -> 0 | H8: 1
B9: =Jugadores!B8 -> Wiliam López | D9: =H9+L9+P9+T9+X9+AB9+AF9+AJ9+AN9+AR9+AV9+AZ9+BD9+BH9+BL9+BP9+BT9+BX9+CB9+CF9+CJ9+CN9+CR9+CV9+CZ9 -> 0 | E9: =I9+M9+Q9+U9+Y9+AC9+AG9+AK9+AO9+AS9+AW9+BA9+BE9+BI9+BM9+BQ9+BU9+BY9+CC9+CG9+CK9+CO9+CS9+CW9+DA9 -> 0 | F9: =J9+N9+R9+V9+Z9+AD9+AH9+AL9+AP9+AT9+AX9+BB9+BF9+BJ9+BN9+BR9+BV9+BZ9+CD9+CH9+CL9+CP9+CT9+CX9 -> 0 | G9: =K9+O9+S9+W9+AA9+AE9+AI9+AM9+AQ9+AU9+AY9+BC9+BG9+BK9+BO9+BS9+BW9+CA9+CE9+CI9+CM9+CQ9+CU9+CY9 -> 0
B10: =Jugadores!B9 -> Luis Lima | D10: =H10+L10+P10+T10+X10+AB10+AF10+AJ10+AN10+AR10+AV10+AZ10+BD10+BH10+BL10+BP10+BT10+BX10+CB10+CF10+CJ10+CN10+CR10+CV10+CZ10 -> 1 | E10: =I10+M10+Q10+U10+Y10+AC10+AG10+AK10+AO10+AS10+AW10+BA10+BE10+BI10+BM10+BQ10+BU10+BY10+CC10+CG10+CK10+CO10+CS10+CW10+DA10 -> 0 | F10: =J10+N10+R10+V10+Z10+AD10+AH10+AL10+AP10+AT10+AX10+BB10+BF10+BJ10+BN10+BR10+BV10+BZ10+CD10+CH10+CL10+CP10+CT10+CX10 -> 0 | G10: =K10+O10+S10+W10+AA10+AE10+AI10+AM10+AQ10+AU10+AY10+BC10+BG10+BK10+BO10+BS10+BW10+CA10+CE10+CI10+CM10+CQ10+CU10+CY10 -> 0 | AJ10: 1
B11: =Jugadores!B10 -> Juan José Jaramillo | D11: =H11+L11+P11+T11+X11+AB11+AF11+AJ11+AN11+AR11+AV11+AZ11+BD11+BH11+BL11+BP11+BT11+BX11+CB11+CF11+CJ11+CN11+CR11+CV11+CZ11 -> 4 | E11: =I11+M11+Q11+U11+Y11+AC11+AG11+AK11+AO11+AS11+AW11+BA11+BE11+BI11+BM11+BQ11+BU11+BY11+CC11+CG11+CK11+CO11+CS11+CW11+DA11 -> 1 | F11: =J11+N11+R11+V11+Z11+AD11+AH11+AL11+AP11+AT11+AX11+BB11+BF11+BJ11+BN11+BR11+BV11+BZ11+CD11+CH11+CL11+CP11+CT11+CX11 -> 0 | G11: =K11+O11+S11+W11+AA11+AE11+AI11+AM11+AQ11+AU11+AY11+BC11+BG11+BK11+BO11+BS11+BW11+CA11+CE11+CI11+CM11+CQ11+CU11+CY11 -> 0 | H11: 1 | Y11: 1 | BH11: 1 | BL11: 2
B12: =Jugadores!B11 -> Yeiner Muñeton | D12: =H12+L12+P12+T12+X12+AB12+AF12+AJ12+AN12+AR12+AV12+AZ12+BD12+BH12+BL12+BP12+BT12+BX12+CB12+CF12+CJ12+CN12+CR12+CV12+CZ12 -> 1 | E12: =I12+M12+Q12+U12+Y12+AC12+AG12+AK12+AO12+AS12+AW12+BA12+BE12+BI12+BM12+BQ12+BU12+BY12+CC12+CG12+CK12+CO12+CS12+CW12+DA12 -> 0 | F12: =J12+N12+R12+V12+Z12+AD12+AH12+AL12+AP12+AT12+AX12+BB12+BF12+BJ12+BN12+BR12+BV12+BZ12+CD12+CH12+CL12+CP12+CT12+CX12 -> 0 | G12: =K12+O12+S12+W12+AA12+AE12+AI12+AM12+AQ12+AU12+AY12+BC12+BG12+BK12+BO12+BS12+BW12+CA12+CE12+CI12+CM12+CQ12+CU12+CY12 -> 0 | BL12: 1
B13: =Jugadores!B12 -> Stiven Ríos | D13: =H13+L13+P13+T13+X13+AB13+AF13+AJ13+AN13+AR13+AV13+AZ13+BD13+BH13+BL13+BP13+BT13+BX13+CB13+CF13+CJ13+CN13+CR13+CV13+CZ13 -> 0 | E13: =I13+M13+Q13+U13+Y13+AC13+AG13+AK13+AO13+AS13+AW13+BA13+BE13+BI13+BM13+BQ13+BU13+BY13+CC13+CG13+CK13+CO13+CS13+CW13+DA13 -> 0 | F13: =J13+N13+R13+V13+Z13+AD13+AH13+AL13+AP13+AT13+AX13+BB13+BF13+BJ13+BN13+BR13+BV13+BZ13+CD13+CH13+CL13+CP13+CT13+CX13 -> 0 | G13: =K13+O13+S13+W13+AA13+AE13+AI13+AM13+AQ13+AU13+AY13+BC13+BG13+BK13+BO13+BS13+BW13+CA13+CE13+CI13+CM13+CQ13+CU13+CY13 -> 0
B14: =Jugadores!B13 -> Isaac Amarís | D14: =H14+L14+P14+T14+X14+AB14+AF14+AJ14+AN14+AR14+AV14+AZ14+BD14+BH14+BL14+BP14+BT14+BX14+CB14+CF14+CJ14+CN14+CR14+CV14+CZ14 -> 0 | E14: =I14+M14+Q14+U14+Y14+AC14+AG14+AK14+AO14+AS14+AW14+BA14+BE14+BI14+BM14+BQ14+BU14+BY14+CC14+CG14+CK14+CO14+CS14+CW14+DA14 -> 0 | F14: =J14+N14+R14+V14+Z14+AD14+AH14+AL14+AP14+AT14+AX14+BB14+BF14+BJ14+BN14+BR14+BV14+BZ14+CD14+CH14+CL14+CP14+CT14+CX14 -> 0 | G14: =K14+O14+S14+W14+AA14+AE14+AI14+AM14+AQ14+AU14+AY14+BC14+BG14+BK14+BO14+BS14+BW14+CA14+CE14+CI14+CM14+CQ14+CU14+CY14 -> 0
B15: =Jugadores!B14 -> Juan José Gaviría | D15: =H15+L15+P15+T15+X15+AB15+AF15+AJ15+AN15+AR15+AV15+AZ15+BD15+BH15+BL15+BP15+BT15+BX15+CB15+CF15+CJ15+CN15+CR15+CV15+CZ15 -> 2 | E15: =I15+M15+Q15+U15+Y15+AC15+AG15+AK15+AO15+AS15+AW15+BA15+BE15+BI15+BM15+BQ15+BU15+BY15+CC15+CG15+CK15+CO15+CS15+CW15+DA15 -> 1 | F15: =J15+N15+R15+V15+Z15+AD15+AH15+AL15+AP15+AT15+AX15+BB15+BF15+BJ15+BN15+BR15+BV15+BZ15+CD15+CH15+CL15+CP15+CT15+CX15 -> 0 | G15: =K15+O15+S15+W15+AA15+AE15+AI15+AM15+AQ15+AU15+AY15+BC15+BG15+BK15+BO15+BS15+BW15+CA15+CE15+CI15+CM15+CQ15+CU15+CY15 -> 0 | AG15: 1 | AJ15: 1 | AV15: 1
B16: =Jugadores!B15 -> José Santoya | D16: =H16+L16+P16+T16+X16+AB16+AF16+AJ16+AN16+AR16+AV16+AZ16+BD16+BH16+BL16+BP16+BT16+BX16+CB16+CF16+CJ16+CN16+CR16+CV16+CZ16 -> 1 | E16: =I16+M16+Q16+U16+Y16+AC16+AG16+AK16+AO16+AS16+AW16+BA16+BE16+BI16+BM16+BQ16+BU16+BY16+CC16+CG16+CK16+CO16+CS16+CW16+DA16 -> 1 | F16: =J16+N16+R16+V16+Z16+AD16+AH16+AL16+AP16+AT16+AX16+BB16+BF16+BJ16+BN16+BR16+BV16+BZ16+CD16+CH16+CL16+CP16+CT16+CX16 -> 0 | G16: =K16+O16+S16+W16+AA16+AE16+AI16+AM16+AQ16+AU16+AY16+BC16+BG16+BK16+BO16+BS16+BW16+CA16+CE16+CI16+CM16+CQ16+CU16+CY16 -> 0 | AK16: 1 | BD16: 1
B17: =Jugadores!B16 -> Jorge Cassiani | D17: =H17+L17+P17+T17+X17+AB17+AF17+AJ17+AN17+AR17+AV17+AZ17+BD17+BH17+BL17+BP17+BT17+BX17+CB17+CF17+CJ17+CN17+CR17+CV17+CZ17 -> 0 | E17: =I17+M17+Q17+U17+Y17+AC17+AG17+AK17+AO17+AS17+AW17+BA17+BE17+BI17+BM17+BQ17+BU17+BY17+CC17+CG17+CK17+CO17+CS17+CW17+DA17 -> 1 | F17: =J17+N17+R17+V17+Z17+AD17+AH17+AL17+AP17+AT17+AX17+BB17+BF17+BJ17+BN17+BR17+BV17+BZ17+CD17+CH17+CL17+CP17+CT17+CX17 -> 0 | G17: =K17+O17+S17+W17+AA17+AE17+AI17+AM17+AQ17+AU17+AY17+BC17+BG17+BK17+BO17+BS17+BW17+CA17+CE17+CI17+CM17+CQ17+CU17+CY17 -> 0 | Y17: 1
B18: =Jugadores!B17 -> Julián Botero Carvajal | D18: =H18+L18+P18+T18+X18+AB18+AF18+AJ18+AN18+AR18+AV18+AZ18+BD18+BH18+BL18+BP18+BT18+BX18+CB18+CF18+CJ18+CN18+CR18+CV18+CZ18 -> 1 | E18: =I18+M18+Q18+U18+Y18+AC18+AG18+AK18+AO18+AS18+AW18+BA18+BE18+BI18+BM18+BQ18+BU18+BY18+CC18+CG18+CK18+CO18+CS18+CW18+DA18 -> 3 | F18: =J18+N18+R18+V18+Z18+AD18+AH18+AL18+AP18+AT18+AX18+BB18+BF18+BJ18+BN18+BR18+BV18+BZ18+CD18+CH18+CL18+CP18+CT18+CX18 -> 0 | G18: =K18+O18+S18+W18+AA18+AE18+AI18+AM18+AQ18+AU18+AY18+BC18+BG18+BK18+BO18+BS18+BW18+CA18+CE18+CI18+CM18+CQ18+CU18+CY18 -> 0 | Q18: 1 | Y18: 1 | AK18: 1 | AR18: 1
B19: Autogoles a favor | AF19: 1 | AV19: 1
B20: Goles por OW | AZ20: 3 | CF20: 3
B21: Gol por jugador Retirado
D22: =H22+L22+P22+T22+X22+AB22+AF22+AJ22+AN22+AR22+AV22+AZ22+BD22+BH22+BL22+BP22+BT22+BX22+CB22+CF22+CJ22+CN22+CR22+CV22+CZ22 -> 38 | E22: =I22+M22+Q22+U22+Y22+AC22+AG22+AK22+AO22+AS22+AW22+BA22+BE22+BI22+BM22+BQ22+BV22+BY22+CD22+CG22+CL22+CO22+CT22+CW22+DB22 -> 10 | F22: =J22+N22+R22+V22+Z22+AD22+AH22+AL22+AP22+AT22+AX22+BB22+BF22+BJ22+BN22+BT22+BX22+CB22+CF22+CJ22+CN22+CR22+CV22+CZ22 -> 5 | G22: =K22+O22+S22+W22+AA22+AE22+AI22+AM22+AQ22+AU22+AY22+BC22+BG22+BK22+BO22+BV22+BY22+CD22+CG22+CL22+CO22+CT22+CW22+DB22 -> 1 | H22: =SUM(H4:H21) -> 2 | I22: =SUM(I4:I21) -> 0 | J22: =SUM(J4:J21) -> 0 | K22: =SUM(K4:K21) -> 0 | L22: =SUM(L4:L21) -> 0 | M22: =SUM(M4:M21) -> 0 | N22: =SUM(N4:N21) -> 0 | O22: =SUM(O4:O21) -> 0 | ... DC22: =SUM(DC4:DC21) -> 0
D23: Total Goles | E23: Total A | F23: Total 2A | G23: Total R | H23: Total Goles | I23: Total A | J23: Total 2A | K23: Total R | L23: Total Goles | M23: Total A | N23: Total 2A | O23: Total R | P23: Total Goles | Q23: Total A | R23: Total 2A | S23: Total R | T23: Total Goles | U23: Total A | V23: Total 2A | W23: Total R | X23: Total Goles | Y23: Total A | Z23: Total 2A | AA23: Total R | AB23: Total Goles | AC23: Total A | AD23: Total 2A | AE23: Total R | AF23: Total Goles | AG23: Total A | AH23: Total 2A | AI23: Total R | AJ23: Total Goles | AK23: Total A | AL23: Total 2A | AM23: Total R | AN23: Total Goles | AO23: Total A | AP23: Total 2A | AQ23: Total R | AR23: Total Goles | AS23: Total A | AT23: Total 2A | AU23: Total R | AV23: Total Goles | AW23: Total A | AX23: Total 2A | AY23: Total R | AZ23: Total Goles | BA23: Total A | BB23: Total 2A | BC23: Total R | BD23: Total Goles | BE23: Total A | BF23: Total 2A | BG23: Total R | BH23: Total Goles | BI23: Total A | BJ23: Total 2A | BK23: Total R | BL23: Total Goles | BM23: Total A | BN23: Total 2A | BO23: Total R | BP23: Total Goles | BQ23: Total A | BR23: Total 2A | BS23: Total R | BT23: Total Goles | BU23: Total A | BV23: Total 2A | BW23: Total R | BX23: Total Goles | BY23: Total A | BZ23: Total 2A | CA23: Total R | CB23: Total Goles | CC23: Total A | CD23: Total 2A | CE23: Total R | CF23: Total Goles | CG23: Total A | CH23: Total 2A | CI23: Total R | CJ23: Total Goles | CK23: Total A | CL23: Total 2A | CM23: Total R | CN23: Total Goles | CO23: Total A | CP23: Total 2A | CQ23: Total R | CR23: Total Goles | CS23: Total A | CT23: Total 2A | CU23: Total R | CV23: Total Goles | CW23: Total A | CX23: Total 2A | CY23: Total R | CZ23: Total Goles | DA23: Total A | DB23: Total 2A | DC23: Total R

Sheet La Amistad
